Workbook

Sheet Bảng kê SS
A1: BẢNG KÊ CHI TIẾT CƯỚC VẬN CHUYỂN SHIPSIDE THÁNG 04/2026
A2: Bảng kê số ngày 30/04/2026
A3: (Kèm theo HĐ GTGT số: ngày 30/04/2026)
A5: NGƯỜI BÁN: CÔNG TY TNHH AMT PHÚC LỘC
A6: Địa chỉ: Số 56B/97 đường Đoàn Kết, Phường Hải An, Thành Phố Hải Phòng, Việt Nam
A7: MST: 0201965047
P8: Cước vận chuyển cont Vỏ
A9: NGƯỜI MUA: CÔNG TY TNHH CẢNG HẢI AN | P9: Cước vận chuyển cont Hàng
A10: Địa chỉ: Tầng 1, Tòa nhà Hải An, Km 2 đường Đình Vũ, P. Đông Hải, TP. Hải Phòng, Việt Nam | P10: tuyến đường
A11: MST: 0201126468 | P11: . Số xe:
P12: . Số cont: | Q12: -
A13: TT | B13: SỐCONT | C13: LOẠI | D13: H/R | E13: TÀU | F13: CHUYẾN | G13: NƠI LẤY CONTAINER | H13: NƠI TRẢ CONTAINER | I13: SỐ XE VC | J13: ĐƠN GIÁ | K13: THUẾ GTGT (8%) | L13: THÀNH TIỀN | M13: Ngày | N13: Ký hiệu cước | O13: Giá dầu TB tháng | P13: Nội dung HĐ | R13: F20 | S13: F40 | T13: E20 | U13: E40
A14: 1 | B14: NSSU0221340 | C14: 20 | D14: H | E14: HAIAN ALFA | F14: 073N | G14: NHĐV | H14: HẢI AN | I14: 15C15033 | J14: {=IF(C14=20,INDEX(CUOC!$C$28:$C$37,MATCH(N14,CUOC!$A$28:$A$37,0),0),INDEX(CUOC!$D$28:$D$37,MATCH(N14,CUOC!$A$28:$A$37,0),0))} -> 386100 | K14: =+J14*0.08 -> 30888 | L14: =+K14+J14 -> 416988 | M14: 46111 | N14: 5 | O14: 34832 | P14: =IF(D14="R",$P$8&C14&$P$10&G14&$Q$12&H14&$P$11&I14,$P$9&C14&$P$10&G14&$Q$12&H14&$P$11&I14) -> Cước vận chuyển cont Hàng 20 tuyến đường NHĐV - HẢI AN. Số xe: 15C15033 | Q14: 1
A15: 2 | B15: HACU2162788 | C15: 20 | D15: H | E15: HAIAN ALFA | F15: 073N | G15: NHĐV | H15: HẢI AN | I15: 15H07524 | J15: {=IF(C15=20,INDEX(CUOC!$C$28:$C$37,MATCH(N15,CUOC!$A$28:$A$37,0),0),INDEX(CUOC!$D$28:$D$37,MATCH(N15,CUOC!$A$28:$A$37,0),0))} -> 386100 | K15: =+J15*0.08 -> 30888 | L15: =+K15+J15 -> 416988 | M15: 46111 | N15: 5 | O15: 34832 | P15: =IF(D15="R",$P$8&C15&$P$10&G15&$Q$12&H15&$P$11&I15,$P$9&C15&$P$10&G15&$Q$12&H15&$P$11&I15) -> Cước vận chuyển cont Hàng 20 tuyến đường NHĐV - HẢI AN. Số xe: 15H07524 | Q15: 1
A16: 3 | B16: HACU2214120 | C16: 20 | D16: H | E16: HAIAN ALFA | F16: 073N | G16: NHĐV | H16: HẢI AN | I16: 15H07524 | J16: {=IF(C16=20,INDEX(CUOC!$C$28:$C$37,MATCH(N16,CUOC!$A$28:$A$37,0),0),INDEX(CUOC!$D$28:$D$37,MATCH(N16,CUOC!$A$28:$A$37,0),0))} -> 386100 | K16: =+J16*0.08 -> 30888 | L16: =+K16+J16 -> 416988 | M16: 46111 | N16: 5 | O16: 34832 | P16: =IF(D16="R",$P$8&C16&$P$10&G16&$Q$12&H16&$P$11&I16,$P$9&C16&$P$10&G16&$Q$12&H16&$P$11&I16) -> Cước vận chuyển cont Hàng 20 tuyến đường NHĐV - HẢI AN. Số xe: 15H07524 | Q16: 1
A17: 4 | B17: HACU2211075 | C17: 20 | D17: H | E17: HAIAN ALFA | F17: 073N | G17: NHĐV | H17: HẢI AN | I17: 15C17442 | J17: {=IF(C17=20,INDEX(CUOC!$C$28:$C$37,MATCH(N17,CUOC!$A$28:$A$37,0),0),INDEX(CUOC!$D$28:$D$37,MATCH(N17,CUOC!$A$28:$A$37,0),0))} -> 386100 | K17: =+J17*0.08 -> 30888 | L17: =+K17+J17 -> 416988 | M17: 46111 | N17: 5 | O17: 34832 | P17: =IF(D17="R",$P$8&C17&$P$10&G17&$Q$12&H17&$P$11&I17,$P$9&C17&$P$10&G17&$Q$12&H17&$P$11&I17) -> Cước vận chuyển cont Hàng 20 tuyến đường NHĐV - HẢI AN. Số xe: 15C17442 | Q17: 1
A18: 5 | B18: HACU2244063 | C18: 20 | D18: H | E18: HAIAN ALFA | F18: 073N | G18: NHĐV | H18: HẢI AN | I18: 15H07644 | J18: {=IF(C18=20,INDEX(CUOC!$C$28:$C$37,MATCH(N18,CUOC!$A$28:$A$37,0),0),INDEX(CUOC!$D$28:$D$37,MATCH(N18,CUOC!$A$28:$A$37,0),0))} -> 386100 | K18: =+J18*0.08 -> 30888 | L18: =+K18+J18 -> 416988 | M18: 46111 | N18: 5 | O18: 34832 | P18: =IF(D18="R",$P$8&C18&$P$10&G18&$Q$12&H18&$P$11&I18,$P$9&C18&$P$10&G18&$Q$12&H18&$P$11&I18) -> Cước vận chuyển cont Hàng 20 tuyến đường NHĐV - HẢI AN. Số xe: 15H07644 | Q18: 1
A19: 6 | B19: CAIU6301385 | C19: 20 | D19: H | E19: HAIAN ALFA | F19: 073N | G19: NHĐV | H19: HẢI AN | I19: 15H07644 | J19: {=IF(C19=20,INDEX(CUOC!$C$28:$C$37,MATCH(N19,CUOC!$A$28:$A$37,0),0),INDEX(CUOC!$D$28:$D$37,MATCH(N19,CUOC!$A$28:$A$37,0),0))} -> 386100 | K19: =+J19*0.08 -> 30888 | L19: =+K19+J19 -> 416988 | M19: 46111 | N19: 5 | O19: 34832 | P19: =IF(D19="R",$P$8&C19&$P$10&G19&$Q$12&H19&$P$11&I19,$P$9&C19&$P$10&G19&$Q$12&H19&$P$11&I19) -> Cước vận chuyển cont Hàng 20 tuyến đường NHĐV - HẢI AN. Số xe: 15H07644 | Q19: 1
A20: 7 | B20: CAAU2139484 | C20: 20 | D20: H | E20: HAIAN ALFA | F20: 073N | G20: NHĐV | H20: HẢI AN | I20: 15C30649 | J20: {=IF(C20=20,INDEX(CUOC!$C$28:$C$37,MATCH(N20,CUOC!$A$28:$A$37,0),0),INDEX(CUOC!$D$28:$D$37,MATCH(N20,CUOC!$A$28:$A$37,0),0))} -> 386100 | K20: =+J20*0.08 -> 30888 | L20: =+K20+J20 -> 416988 | M20: 46110 | N20: 5 | O20: 34832 | P20: =IF(D20="R",$P$8&C20&$P$10&G20&$Q$12&H20&$P$11&I20,$P$9&C20&$P$10&G20&$Q$12&H20&$P$11&I20) -> Cước vận chuyển cont Hàng 20 tuyến đường NHĐV - HẢI AN. Số xe: 15C30649 | Q20: 1
A21: 8 | B21: SEGU3973336 | C21: 20 | D21: H | E21: HAIAN ALFA | F21: 073N | G21: NHĐV | H21: HẢI AN | I21: 15C17442 | J21: {=IF(C21=20,INDEX(CUOC!$C$28:$C$37,MATCH(N21,CUOC!$A$28:$A$37,0),0),INDEX(CUOC!$D$28:$D$37,MATCH(N21,CUOC!$A$28:$A$37,0),0))} -> 386100 | K21: =+J21*0.08 -> 30888 | L21: =+K21+J21 -> 416988 | M21: 46110 | N21: 5 | O21: 34832 | P21: =IF(D21="R",$P$8&C21&$P$10&G21&$Q$12&H21&$P$11&I21,$P$9&C21&$P$10&G21&$Q$12&H21&$P$11&I21) -> Cước vận chuyển cont Hàng 20 tuyến đường NHĐV - HẢI AN. Số xe: 15C17442 | Q21: 1
A22: 9 | B22: SEKU1802719 | C22: 20 | D22: H | E22: HAIAN ALFA | F22: 073N | G22: NHĐV | H22: HẢI AN | I22: 15C17442 | J22: {=IF(C22=20,INDEX(CUOC!$C$28:$C$37,MATCH(N22,CUOC!$A$28:$A$37,0),0),INDEX(CUOC!$D$28:$D$37,MATCH(N22,CUOC!$A$28:$A$37,0),0))} -> 386100 | K22: =+J22*0.08 -> 30888 | L22: =+K22+J22 -> 416988 | M22: 46110 | N22: 5 | O22: 34832 | P22: =IF(D22="R",$P$8&C22&$P$10&G22&$Q$12&H22&$P$11&I22,$P$9&C22&$P$10&G22&$Q$12&H22&$P$11&I22) -> Cước vận chuyển cont Hàng 20 tuyến đường NHĐV - HẢI AN. Số xe: 15C17442 | Q22: 1
A23: 10 | B23: HACU2212359 | C23: 20 | D23: H | E23: HAIAN ALFA | F23: 073N | G23: NHĐV | H23: HẢI AN | I23: 15C30649 | J23: {=IF(C23=20,INDEX(CUOC!$C$28:$C$37,MATCH(N23,CUOC!$A$28:$A$37,0),0),INDEX(CUOC!$D$28:$D$37,MATCH(N23,CUOC!$A$28:$A$37,0),0))} -> 386100 | K23: =+J23*0.08 -> 30888 | L23: =+K23+J23 -> 416988 | M23: 46110 | N23: 5 | O23: 34832 | P23: =IF(D23="R",$P$8&C23&$P$10&G23&$Q$12&H23&$P$11&I23,$P$9&C23&$P$10&G23&$Q$12&H23&$P$11&I23) -> Cước vận chuyển cont Hàng 20 tuyến đường NHĐV - HẢI AN. Số xe: 15C30649 | Q23: 1
A24: 11 | B24: SEKU1802724 | C24: 20 | D24: H | E24: HAIAN ALFA | F24: 073N | G24: NHĐV | H24: HẢI AN | I24: 15H07788 | J24: {=IF(C24=20,INDEX(CUOC!$C$28:$C$37,MATCH(N24,CUOC!$A$28:$A$37,0),0),INDEX(CUOC!$D$28:$D$37,MATCH(N24,CUOC!$A$28:$A$37,0),0))} -> 386100 | K24: =+J24*0.08 -> 30888 | L24: =+K24+J24 -> 416988 | M24: 46110 | N24: 5 | O24: 34832 | P24: =IF(D24="R",$P$8&C24&$P$10&G24&$Q$12&H24&$P$11&I24,$P$9&C24&$P$10&G24&$Q$12&H24&$P$11&I24) -> Cước vận chuyển cont Hàng 20 tuyến đường NHĐV - HẢI AN. Số xe: 15H07788 | Q24: 1
A25: 12 | B25: HACU2214958 | C25: 20 | D25: H | E25: HAIAN ALFA | F25: 073N | G25: NHĐV | H25: HẢI AN | I25: 15H08574 | J25: {=IF(C25=20,INDEX(CUOC!$C$28:$C$37,MATCH(N25,CUOC!$A$28:$A$37,0),0),INDEX(CUOC!$D$28:$D$37,MATCH(N25,CUOC!$A$28:$A$37,0),0))} -> 386100 | K25: =+J25*0.08 -> 30888 | L25: =+K25+J25 -> 416988 | M25: 46110 | N25: 5 | O25: 34832 | P25: =IF(D25="R",$P$8&C25&$P$10&G25&$Q$12&H25&$P$11&I25,$P$9&C25&$P$10&G25&$Q$12&H25&$P$11&I25) -> Cước vận chuyển cont Hàng 20 tuyến đường NHĐV - HẢI AN. Số xe: 15H08574 | Q25: 1
... A363: 350 | B363: GAOU7791590 | C363: 40 | D363: H | E363: HAIAN DELL | F363: 037S | G363: HẢI AN | H363: NHĐV | I363: 15H07135 | J363: {=IF(C363=20,INDEX(CUOC!$C$28:$C$37,MATCH(N363,CUOC!$A$28:$A$37,0),0),INDEX(CUOC!$D$28:$D$37,MATCH(N363,CUOC!$A$28:$A$37,0),0))} -> 448500 | K363: =+J363*0.08 -> 35880 | L363: =+K363+J363 -> 484380 | M363: 46128 | N363: 5 | O363: 34832 | P363: =IF(D363="R",$P$8&C363&$P$10&G363&$Q$12&H363&$P$11&I363,$P$9&C363&$P$10&G363&$Q$12&H363&$P$11&I363) -> Cước vận chuyển cont Hàng 40 tuyến đường HẢI AN - NHĐV. Số xe: 15H07135 | Q363: 1
A364: 351 | B364: TEMU5245336 | C364: 20 | D364: H | E364: HAIAN DELL | F364: V.036S | G364: HẢI AN | H364: NHĐV | I364: 15C09877 | J364: {=IF(C364=20,INDEX(CUOC!$C$28:$C$37,MATCH(N364,CUOC!$A$28:$A$37,0),0),INDEX(CUOC!$D$28:$D$37,MATCH(N364,CUOC!$A$28:$A$37,0),0))} -> 386100 | K364: =+J364*0.08 -> 30888 | L364: =+K364+J364 -> 416988 | M364: 03/04/2026 | N364: 5 | O364: 34832 | P364: =IF(D364="R",$P$8&C364&$P$10&G364&$Q$12&H364&$P$11&I364,$P$9&C364&$P$10&G364&$Q$12&H364&$P$11&I364) -> Cước vận chuyển cont Hàng 20 tuyến đường HẢI AN - NHĐV. Số xe: 15C09877 | Q364: 1
A365: 352 | B365: TEMU5280255 | C365: 20 | D365: H | E365: HAIAN DELL | F365: V.036S | G365: HẢI AN | H365: NHĐV | I365: 15C09877 | J365: {=IF(C365=20,INDEX(CUOC!$C$28:$C$37,MATCH(N365,CUOC!$A$28:$A$37,0),0),INDEX(CUOC!$D$28:$D$37,MATCH(N365,CUOC!$A$28:$A$37,0),0))} -> 386100 | K365: =+J365*0.08 -> 30888 | L365: =+K365+J365 -> 416988 | M365: 03/04/2026 | N365: 5 | O365: 34832 | P365: =IF(D365="R",$P$8&C365&$P$10&G365&$Q$12&H365&$P$11&I365,$P$9&C365&$P$10&G365&$Q$12&H365&$P$11&I365) -> Cước vận chuyển cont Hàng 20 tuyến đường HẢI AN - NHĐV. Số xe: 15C09877 | Q365: 1
A366: 353 | B366: CAIU3692753 | C366: 20 | D366: H | E366: HAIAN DELL | F366: V.036S | G366: HẢI AN | H366: NHĐV | I366: 15H08574 | J366: {=IF(C366=20,INDEX(CUOC!$C$28:$C$37,MATCH(N366,CUOC!$A$28:$A$37,0),0),INDEX(CUOC!$D$28:$D$37,MATCH(N366,CUOC!$A$28:$A$37,0),0))} -> 386100 | K366: =+J366*0.08 -> 30888 | L366: =+K366+J366 -> 416988 | M366: 03/04/2026 | N366: 5 | O366: 34832 | P366: =IF(D366="R",$P$8&C366&$P$10&G366&$Q$12&H366&$P$11&I366,$P$9&C366&$P$10&G366&$Q$12&H366&$P$11&I366) -> Cước vận chuyển cont Hàng 20 tuyến đường HẢI AN - NHĐV. Số xe: 15H08574 | Q366: 1
A367: 354 | B367: TCLU7643780 | C367: 20 | D367: H | E367: HAIAN DELL | F367: V.036S | G367: HẢI AN | H367: NHĐV | I367: 15C09877 | J367: {=IF(C367=20,INDEX(CUOC!$C$28:$C$37,MATCH(N367,CUOC!$A$28:$A$37,0),0),INDEX(CUOC!$D$28:$D$37,MATCH(N367,CUOC!$A$28:$A$37,0),0))} -> 386100 | K367: =+J367*0.08 -> 30888 | L367: =+K367+J367 -> 416988 | M367: 03/04/2026 | N367: 5 | O367: 34832 | P367: =IF(D367="R",$P$8&C367&$P$10&G367&$Q$12&H367&$P$11&I367,$P$9&C367&$P$10&G367&$Q$12&H367&$P$11&I367) -> Cước vận chuyển cont Hàng 20 tuyến đường HẢI AN - NHĐV. Số xe: 15C09877 | Q367: 1
A368: 355 | B368: TCKU3754284 | C368: 20 | D368: H | E368: HAIAN DELL | F368: V.036S | G368: HẢI AN | H368: NHĐV | I368: 15C09877 | J368: {=IF(C368=20,INDEX(CUOC!$C$28:$C$37,MATCH(N368,CUOC!$A$28:$A$37,0),0),INDEX(CUOC!$D$28:$D$37,MATCH(N368,CUOC!$A$28:$A$37,0),0))} -> 386100 | K368: =+J368*0.08 -> 30888 | L368: =+K368+J368 -> 416988 | M368: 03/04/2026 | N368: 5 | O368: 34832 | P368: =IF(D368="R",$P$8&C368&$P$10&G368&$Q$12&H368&$P$11&I368,$P$9&C368&$P$10&G368&$Q$12&H368&$P$11&I368) -> Cước vận chuyển cont Hàng 20 tuyến đường HẢI AN - NHĐV. Số xe: 15C09877 | Q368: 1
A369: 356 | B369: TGBU3301385 | C369: 20 | D369: H | E369: HAIAN DELL | F369: V.036S | G369: HẢI AN | H369: NHĐV | I369: 15C09877 | J369: {=IF(C369=20,INDEX(CUOC!$C$28:$C$37,MATCH(N369,CUOC!$A$28:$A$37,0),0),INDEX(CUOC!$D$28:$D$37,MATCH(N369,CUOC!$A$28:$A$37,0),0))} -> 386100 | K369: =+J369*0.08 -> 30888 | L369: =+K369+J369 -> 416988 | M369: 03/04/2026 | N369: 5 | O369: 34832 | P369: =IF(D369="R",$P$8&C369&$P$10&G369&$Q$12&H369&$P$11&I369,$P$9&C369&$P$10&G369&$Q$12&H369&$P$11&I369) -> Cước vận chuyển cont Hàng 20 tuyến đường HẢI AN - NHĐV. Số xe: 15C09877 | Q369: 1
A370: 357 | B370: CAAU9568217 | C370: 20 | D370: H | E370: HAIAN DELL | F370: V.036S | G370: HẢI AN | H370: NHĐV | I370: 15H08574 | J370: {=IF(C370=20,INDEX(CUOC!$C$28:$C$37,MATCH(N370,CUOC!$A$28:$A$37,0),0),INDEX(CUOC!$D$28:$D$37,MATCH(N370,CUOC!$A$28:$A$37,0),0))} -> 386100 | K370: =+J370*0.08 -> 30888 | L370: =+K370+J370 -> 416988 | M370: 03/04/2026 | N370: 5 | O370: 34832 | P370: =IF(D370="R",$P$8&C370&$P$10&G370&$Q$12&H370&$P$11&I370,$P$9&C370&$P$10&G370&$Q$12&H370&$P$11&I370) -> Cước vận chuyển cont Hàng 20 tuyến đường HẢI AN - NHĐV. Số xe: 15H08574 | Q370: 1
A371: 358 | B371: TCLU6636894 | C371: 20 | D371: H | E371: HAIAN DELL | F371: V.036S | G371: HẢI AN | H371: NHĐV | I371: 15H08574 | J371: {=IF(C371=20,INDEX(CUOC!$C$28:$C$37,MATCH(N371,CUOC!$A$28:$A$37,0),0),INDEX(CUOC!$D$28:$D$37,MATCH(N371,CUOC!$A$28:$A$37,0),0))} -> 386100 | K371: =+J371*0.08 -> 30888 | L371: =+K371+J371 -> 416988 | M371: 03/04/2026 | N371: 5 | O371: 34832 | P371: =IF(D371="R",$P$8&C371&$P$10&G371&$Q$12&H371&$P$11&I371,$P$9&C371&$P$10&G371&$Q$12&H371&$P$11&I371) -> Cước vận chuyển cont Hàng 20 tuyến đường HẢI AN - NHĐV. Số xe: 15H08574 | Q371: 1
A372: 359 | B372: TRHU4970898 | C372: 20 | D372: H | E372: HAIAN DELL | F372: V.036S | G372: HẢI AN | H372: NHĐV | I372: 15H08574 | J372: {=IF(C372=20,INDEX(CUOC!$C$28:$C$37,MATCH(N372,CUOC!$A$28:$A$37,0),0),INDEX(CUOC!$D$28:$D$37,MATCH(N372,CUOC!$A$28:$A$37,0),0))} -> 386100 | K372: =+J372*0.08 -> 30888 | L372: =+K372+J372 -> 416988 | M372: 03/04/2026 | N372: 5 | O372: 34832 | P372: =IF(D372="R",$P$8&C372&$P$10&G372&$Q$12&H372&$P$11&I372,$P$9&C372&$P$10&G372&$Q$12&H372&$P$11&I372) -> Cước vận chuyển cont Hàng 20 tuyến đường HẢI AN - NHĐV. Số xe: 15H08574 | Q372: 1
A373: 360 | B373: BEAU5250144 | C373: 20 | D373: H | E373: HAIAN DELL | F373: V.036S | G373: HẢI AN | H373: NHĐV | I373: 15H08574 | J373: {=IF(C373=20,INDEX(CUOC!$C$28:$C$37,MATCH(N373,CUOC!$A$28:$A$37,0),0),INDEX(CUOC!$D$28:$D$37,MATCH(N373,CUOC!$A$28:$A$37,0),0))} -> 386100 | K373: =+J373*0.08 -> 30888 | L373: =+K373+J373 -> 416988 | M373: 03/04/2026 | N373: 5 | O373: 34832 | P373: =IF(D373="R",$P$8&C373&$P$10&G373&$Q$12&H373&$P$11&I373,$P$9&C373&$P$10&G373&$Q$12&H373&$P$11&I373) -> Cước vận chuyển cont Hàng 20 tuyến đường HẢI AN - NHĐV. Số xe: 15H08574 | Q373: 1
A374: 361 | B374: SEKU1943091 | C374: 20 | D374: H | E374: HAIAN BETA | F374: V.060S | G374: HẢI AN | H374: NHĐV | I374: 15H08574 | J374: {=IF(C374=20,INDEX(CUOC!$C$28:$C$37,MATCH(N374,CUOC!$A$28:$A$37,0),0),INDEX(CUOC!$D$28:$D$37,MATCH(N374,CUOC!$A$28:$A$37,0),0))} -> 386100 | K374: =+J374*0.08 -> 30888 | L374: =+K374+J374 -> 416988 | M374: 05/04/2026 | N374: 5 | O374: 34832 | P374: =IF(D374="R",$P$8&C374&$P$10&G374&$Q$12&H374&$P$11&I374,$P$9&C374&$P$10&G374&$Q$12&H374&$P$11&I374) -> Cước vận chuyển cont Hàng 20 tuyến đường HẢI AN - NHĐV. Số xe: 15H08574 | Q374: 1
A375: 362 | B375: HACU2244459 | C375: 20 | D375: H | E375: HAIAN BETA | F375: V.060S | G375: HẢI AN | H375: NHĐV | I375: 15C09877 | J375: {=IF(C375=20,INDEX(CUOC!$C$28:$C$37,MATCH(N375,CUOC!$A$28:$A$37,0),0),INDEX(CUOC!$D$28:$D$37,MATCH(N375,CUOC!$A$28:$A$37,0),0))} -> 386100 | K375: =+J375*0.08 -> 30888 | L375: =+K375+J375 -> 416988 | M375: 05/04/2026 | N375: 5 | O375: 34832 | P375: =IF(D375="R",$P$8&C375&$P$10&G375&$Q$12&H375&$P$11&I375,$P$9&C375&$P$10&G375&$Q$12&H375&$P$11&I375) -> Cước vận chuyển cont Hàng 20 tuyến đường HẢI AN - NHĐV. Số xe: 15C09877 | Q375: 1
... A427: 414 | B427: FBLU0217236 | C427: 40 | D427: H | E427: HAIAN LINK | F427: V.138S | G427: HẢI AN | H427: NHĐV | I427: 15H08574 | J427: {=IF(C427=20,INDEX(CUOC!$C$28:$C$37,MATCH(N427,CUOC!$A$28:$A$37,0),0),INDEX(CUOC!$D$28:$D$37,MATCH(N427,CUOC!$A$28:$A$37,0),0))} -> 448500 | K427: =+J427*0.08 -> 35880 | L427: =+K427+J427 -> 484380 | M427: 29/03/2026 | N427: 5 | O427: 34832 | P427: =IF(D427="R",$P$8&C427&$P$10&G427&$Q$12&H427&$P$11&I427,$P$9&C427&$P$10&G427&$Q$12&H427&$P$11&I427) -> Cước vận chuyển cont Hàng 40 tuyến đường HẢI AN - NHĐV. Số xe: 15H08574 | Q427: 1
A430: TÔNG CỘNG | J430: =SUM(J14:J427) -> 168831000 | K430: =SUM(K14:K427) -> 13506480 | L430: =SUM(L14:L427) -> 182337480
J432: Hải phòng, ngày 30 tháng 04 năm 2026
...

Sheet Sheet2
A3: Row Labels | B3: Sum of SỐ CHUYẾN | C3: Sum of ĐƠN GIÁ
A4: Cước vận chuyển cont Hàng 20 tuyến đường HẢI AN - NHĐV. Số xe: 15C09877 | B4: 39 | C4: 15057900 | E4: 39 | F4: 15057900 | G4: =F4/E4 -> 386100
A5: Cước vận chuyển cont Hàng 20 tuyến đường HẢI AN - NHĐV. Số xe: 15C15033 | B5: 15 | C5: 5791500 | E5: 15 | F5: 5791500 | G5: =F5/E5 -> 386100
A6: Cước vận chuyển cont Hàng 20 tuyến đường HẢI AN - NHĐV. Số xe: 15C17301 | B6: 16 | C6: 6177600 | E6: 16 | F6: 6177600 | G6: =F6/E6 -> 386100
A7: Cước vận chuyển cont Hàng 20 tuyến đường HẢI AN - NHĐV. Số xe: 15C17442 | B7: 8 | C7: 3088800 | E7: 8 | F7: 3088800 | G7: =F7/E7 -> 386100
A8: Cước vận chuyển cont Hàng 20 tuyến đường HẢI AN - NHĐV. Số xe: 15C30649 | B8: 14 | C8: 5405400 | E8: 14 | F8: 5405400 | G8: =F8/E8 -> 386100
A9: Cước vận chuyển cont Hàng 20 tuyến đường HẢI AN - NHĐV. Số xe: 15H06892 | B9: 2 | C9: 772200 | E9: 2 | F9: 772200 | G9: =F9/E9 -> 386100
A10: Cước vận chuyển cont Hàng 20 tuyến đường HẢI AN - NHĐV. Số xe: 15H07135 | B10: 16 | C10: 6177600 | E10: 16 | F10: 6177600 | G10: =F10/E10 -> 386100
A11: Cước vận chuyển cont Hàng 20 tuyến đường HẢI AN - NHĐV. Số xe: 15H07524 | B11: 24 | C11: 9266400 | E11: 24 | F11: 9266400 | G11: =F11/E11 -> 386100
A12: Cước vận chuyển cont Hàng 20 tuyến đường HẢI AN - NHĐV. Số xe: 15H07644 | B12: 12 | C12: 4633200 | E12: 12 | F12: 4633200 | G12: =F12/E12 -> 386100
A13: Cước vận chuyển cont Hàng 20 tuyến đường HẢI AN - NHĐV. Số xe: 15H07788 | B13: 20 | C13: 7722000 | E13: 20 | F13: 7722000 | G13: =F13/E13 -> 386100
A14: Cước vận chuyển cont Hàng 20 tuyến đường HẢI AN - NHĐV. Số xe: 15H08574 | B14: 39 | C14: 15057900 | E14: 39 | F14: 15057900 | G14: =F14/E14 -> 386100
A15: Cước vận chuyển cont Hàng 20 tuyến đường HẢI AN - NHĐV. Số xe: 15H12925 | B15: 1 | C15: 386100 | E15: 1 | F15: 386100 | G15: =F15/E15 -> 386100
... A60: Cước vận chuyển cont Hàng 40 tuyến đường NHĐV - HẢI AN. Số xe: 15H20645 | B60: 7 | C60: 3139500 | E60: 7 | F60: 3139500 | G60: =F60/E60 -> 448500
A61: (blank)
A62: Grand Total | B62: 414 | C62: 168831000

Sheet Sheet1
A1: Nội dung HĐ | B1: ĐƠN GIÁ | C1: SỐ CHUYẾN
A2: Cước vận chuyển cont Hàng 20 tuyến đường NHĐV - HẢI AN. Số xe: 15C15033 | B2: 386100 | C2: 1
A3: Cước vận chuyển cont Hàng 20 tuyến đường NHĐV - HẢI AN. Số xe: 15H07524 | B3: 386100 | C3: 1
A4: Cước vận chuyển cont Hàng 20 tuyến đường NHĐV - HẢI AN. Số xe: 15H07524 | B4: 386100 | C4: 1
A5: Cước vận chuyển cont Hàng 20 tuyến đường NHĐV - HẢI AN. Số xe: 15C17442 | B5: 386100 | C5: 1
A6: Cước vận chuyển cont Hàng 20 tuyến đường NHĐV - HẢI AN. Số xe: 15H07644 | B6: 386100 | C6: 1
A7: Cước vận chuyển cont Hàng 20 tuyến đường NHĐV - HẢI AN. Số xe: 15H07644 | B7: 386100 | C7: 1
A8: Cước vận chuyển cont Hàng 20 tuyến đường NHĐV - HẢI AN. Số xe: 15C30649 | B8: 386100 | C8: 1
A9: Cước vận chuyển cont Hàng 20 tuyến đường NHĐV - HẢI AN. Số xe: 15C17442 | B9: 386100 | C9: 1
A10: Cước vận chuyển cont Hàng 20 tuyến đường NHĐV - HẢI AN. Số xe: 15C17442 | B10: 386100 | C10: 1
A11: Cước vận chuyển cont Hàng 20 tuyến đường NHĐV - HẢI AN. Số xe: 15C30649 | B11: 386100 | C11: 1
A12: Cước vận chuyển cont Hàng 20 tuyến đường NHĐV - HẢI AN. Số xe: 15H07788 | B12: 386100 | C12: 1
A13: Cước vận chuyển cont Hàng 20 tuyến đường NHĐV - HẢI AN. Số xe: 15H08574 | B13: 386100 | C13: 1
... A415: Cước vận chuyển cont Hàng 40 tuyến đường HẢI AN - NHĐV. Số xe: 15H08574 | B415: 448500 | C415: 1

Sheet CUOC
B1: ĐỊA ĐIỂM VẬN CHUYỂN | C1: CƯỚC VÂN CHUYỂN HÀNG (VNĐ) | E1: CƯỚC VẬN CHUYỂN VỎ (VNĐ)
A2: STT
C3: 20’ | D3: 40’ | E3: 20’ | F3: 40’
A4: 1 | B4: Hải An – Nam Hải,Đoạn Xá, TVN | C4: 308000 | D4: 356000 | E4: 194000 | F4: 318000
A5: 2 | B5: Hải An – Nam Hải Đình Vũ, Vip Greenport | C5: 297000 | D5: 345000 | E5: 186000 | F5: 308000
A6: 3 | B6: Hải An – Chùa vẽ, Greenport | C6: 273000 | D6: 344000 | E6: 166000 | F6: 293000
A7: 4 | B7: Hải An – Cảng 128, Cảng 189, PTSC | C7: 273000 | D7: 344000 | E7: 166000 | F7: 293000
A8: 5 | B8: Hải An – Cảng Đình Vũ, Tân Vũ | C8: 273000 | D8: 344000 | E8: 166000 | F8: 293000
A9: 6 | B9: Hải An – G.Forune 2, Sao Á DC, Yusen, SITC. | C9: 273000 | D9: 344000 | E9: 166000 | F9: 293000
A10: 7 | B10: Hải An - PANHAIAN | C10: 308000 | D10: 356000 | E10: 194000 | F10: 318000
A11: 8 | B11: Hải An- Nam Phát, Vietfracht, Northfreight, Sao Đỏ | C11: 273000 | D11: 344000 | E11: 166000 | F11: 293000
A12: 9 | B12: Hải An – ECS, Phương Đông, Tasa Minh Thành | C12: 213000 | D12: 273000 | E12: 136000 | F12: 223000
A13: 10 | B13: Hải An – MIPEC (MPC) | C13: 424000 | D13: 424000 | E13: 194000 | F13: 388000
A14: 11 | B14: PTSC – Bãi Pan Hải An | C14: 368000 | D14: 368000 | E14: 330000 | F14: 330000
A15: 12 | B15: Hải An – Lạch Huyện | C15: 800000 | D15: 800000 | E15: 800000 | F15: 750000
A16: 13 | B16: Hải An – Lạch Huyện (5 cont vỏ/ 1 chuyến) | F16: =F15*2 -> 1500000
A17: STT | B17: ĐỊA ĐIỂM VẬN CHUYỂN ĐG NGẮN | C17: Cước vận chuyển lượt đi và lượt về Hàng 20, 40feet
A18: 1 | B18: Hải An – Tasa ( Máy soi cố định) | C18: 600000
A19: 2 | B19: Hải An – Cảng Tân Vũ, Đình Vũ | C19: 800000
B20: ( Máy soi di động )
A21: 3 | B21: Hải An – Nam Hải Đình Vũ, Vip Greenport | C21: 1000000
B22: ( Máy soi di động )
C26: F20 | D26: F40
B27: GIÁ HỢP ĐỒNG | C27: 297000 | D27: 345000
A28: 1 | B28: 22-25 | C28: 326700 | D28: 379500 | E28: tăng 10%
A29: 2 | B29: 25-28 | C29: 341550 | D29: 396750 | E29: tăng 15%
A30: 3 | B30: 28-31 | C30: 356400 | D30: 414000 | E30: tăng 20%
A31: 4 | B31: 31-34 | C31: 371250 | D31: 431250 | E31: tăng 25%
A32: 5 | B32: 34-37 | C32: 386100 | D32: 448500 | E32: tăng 30%
A33: 6 | B33: 37-40 | C33: 400950 | D33: 465750 | E33: tăng 35%
A34: 7 | B34: 40-43 | C34: 415800 | D34: 483000 | E34: tăng 40%
A35: 8 | B35: 43-46 | C35: 430650 | D35: 500250 | E35: tăng 45%
A36: 9 | B36: 46-49 | C36: 445500 | D36: 517500 | E36: tăng 50%
A37: 10 | B37: 49-52 | C37: 460350 | D37: 534750 | E37: tăng 55%
