Workbook
Name TaxTV: 10%
Name TaxXL: 5%
Name WE_ARE_VERY_PLEASED_TO_ADVISE_YOU_THE_MLO_S_CARGO_HAVE_BEEN_LOADED: #REF!
Name WE_ARE_VERY_PLEASED_TO_ADVISE_YOU_THE_MLO_S_CARGO_HAVE_BEEN_LOADED: #REF!
Name WE_ARE_VERY_PLEASED_TO_ADVISE_YOU_THE_MLO_S_CARGO_HAVE_BEEN_LOADED: #REF!
Name WE_ARE_VERY_PLEASED_TO_ADVISE_YOU_THE_MLO_S_CARGO_HAVE_BEEN_LOADED: #REF!
Name WE_ARE_VERY_PLEASED_TO_ADVISE_YOU_THE_MLO_S_CARGO_HAVE_BEEN_LOADED: #REF!

Sheet 00000000

Sheet SINGAPORE
A1: FINAL LIST OF LOADING CONTAINERS
A2: VESSEL: | C2: =TOTAL!E2 -> 0 | H2: PORT OF LOADING : HAI PHONG
A3: VOY: | B3: =+TOTAL!D3 -> 037S | D3: ATA: | E3: =+TOTAL!H3:I3 -> #VALUE! | H3: PORT OF DISCHARGING : SINGAPORE
A4: FLAG: | B4: =TOTAL!D4:E4 -> #VALUE! | D4: ATD: | E4: =+TOTAL!H4:I4 -> #VALUE! | H4: SHIPPING AGENT : HAIAN AGENCY & LOGISTICS COMPANY LIMITED
A6: HAI AN AGENCY & LOGISTICS CO.,LTD | J6: SINGAPORE
A7: 2nd FLOOR HA BUILDING - KM2 DINH VU ROAD - HA DIST - HAI PHONG
A8: TEL : +84-31-3260446 FAX : +84-31-3260577
A10: SQ | B10: OPR | C10: LINE | D10: CONTNo. | E10: SEALNo. | F10: CELL | G10: F | H10: SIZE | I10: VGM (KGM) | J10: DESCRIPTION OFGOODS | K10: CY | L10: REMARKS | M10: Booking No | N10: Shipper | O10: CONNECTING VESSEL | P10: POD | Q10: SALES/ MKT
A11: 1 | R11: =[2]!checkcont(D11) -> #NAME? | S11: =G11&H11
A12: 2 | R12: =[2]!checkcont(D12) -> #NAME? | S12: =G12&H12
A13: 3 | R13: =[2]!checkcont(D13) -> #NAME? | S13: =G13&H13
A14: 4 | R14: =[2]!checkcont(D14) -> #NAME? | S14: =G14&H14
A15: 5 | R15: =[2]!checkcont(D15) -> #NAME? | S15: =G15&H15
A16: 6 | R16: =[2]!checkcont(D16) -> #NAME? | S16: =G16&H16
A17: 7 | R17: =[2]!checkcont(D17) -> #NAME? | S17: =G17&H17
A18: 8 | R18: =[2]!checkcont(D18) -> #NAME? | S18: =G18&H18
A19: 9 | R19: =[2]!checkcont(D19) -> #NAME? | S19: =G19&H19
A20: 10 | R20: =[2]!checkcont(D20) -> #NAME? | S20: =G20&H20
A21: 11 | R21: =[2]!checkcont(D21) -> #NAME? | S21: =G21&H21
A22: 12 | R22: =[2]!checkcont(D22) -> #NAME? | S22: =G22&H22
... A510: 500 | R510: =[2]!checkcont(D510) -> #NAME? | S510: =G510&H510

Sheet CAT LAI
A1: FINAL LIST OF LOADING CONTAINERS
A2: VESSEL: | C2: =TOTAL!E2 -> 0 | H2: PORT OF LOADING : HAI PHONG
A3: VOY: | B3: =+TOTAL!D3 -> 037S | D3: ATA: | E3: =+TOTAL!H3:I3 -> #VALUE! | H3: PORT OF DISCHARGING : CAT LAI
A4: FLAG: | B4: =TOTAL!D4:E4 -> #VALUE! | D4: ATD: | E4: =+TOTAL!H4:I4 -> #VALUE! | H4: SHIPPING AGENT : HAIAN AGENCY & LOGISTICS COMPANY LIMITED
A6: HAI AN AGENCY & LOGISTICS CO.,LTD | J6: CAT LAI
A7: 2nd FLOOR HA BUILDING - KM2 DINH VU ROAD - HA DIST - HAI PHONG
A8: TEL : +84-31-3260446 FAX : +84-31-3260577
A10: SQ | B10: OPR | C10: LINE | D10: CONTNo. | E10: SEALNo. | F10: CELL | G10: F | H10: SIZE | I10: VGM (KGM) | J10: DESCRIPTION OFGOODS | K10: CY | L10: REMARKS | M10: Booking No | N10: Shipper | O10: CONNECTING VESSEL | P10: POD | Q10: SALES/ MKT
A11: 1 | R11: =[2]!checkcont(D11) -> #NAME? | S11: =G11&H11
A12: 2 | R12: =[2]!checkcont(D12) -> #NAME? | S12: =G12&H12
A13: 3 | R13: =[2]!checkcont(D13) -> #NAME? | S13: =G13&H13
A14: 4 | R14: =[2]!checkcont(D14) -> #NAME? | S14: =G14&H14
A15: 5 | R15: =[2]!checkcont(D15) -> #NAME? | S15: =G15&H15
A16: 6 | R16: =[2]!checkcont(D16) -> #NAME? | S16: =G16&H16
A17: 7 | R17: =[2]!checkcont(D17) -> #NAME? | S17: =G17&H17
A18: 8 | R18: =[2]!checkcont(D18) -> #NAME? | S18: =G18&H18
A19: 9 | R19: =[2]!checkcont(D19) -> #NAME? | S19: =G19&H19
A20: 10 | R20: =[2]!checkcont(D20) -> #NAME? | S20: =G20&H20
A21: 11 | R21: =[2]!checkcont(D21) -> #NAME? | S21: =G21&H21
A22: 12 | R22: =[2]!checkcont(D22) -> #NAME? | S22: =G22&H22
... A510: 500 | R510: =[2]!checkcont(D510) -> #NAME? | S510: =G510&H510

Sheet TOTAL
A1: FINAL LIST OF LOADING CONTAINERS
A2: VESSEL: | D2: HAIAN DELL | H2: HAIAN DELL | I2: 037S | J2: PORT OF LOADING : HAI PHONG
A3: VOY: | D3: 037S | F3: ATA: | G3: 46129 | J3: PORT OF DISCHARGING : SINGAPORE
A4: FLAG: | D4: =IF(E2="PACIFIC GRACE","PANAMA","VIET NAM") -> VIET NAM | F4: ATD: | G4: 46130 | J4: SHIPPING AGENT : HAIAN AGENCY & LOGISTICS COMPANY LIMITED
A6: HAI AN AGENCY & LOGISTICS CO.,LTD | M6: TOTAL
A7: 2nd FLOOR HA BUILDING - KM2 DINH VU ROAD - HA DIST - HAI PHONG
A8: TEL : +84-31-3260446 FAX : +84-31-3260577 | I8: =SUBTOTAL(3,$I$11:$I$1048576) -> 28 | K8: =SUM(K11:K872) -> 13072.978 | O8: =SUBTOTAL(3,$O$11:$O$1048576) -> 28
A10: SQ | B10: POD | C10: POL | D10: OPR | E10: LINE | F10: CONTNo. | G10: SEAL | H10: CELL | I10: F | J10: SIZE | K10: VGM (KGM) | L10: DESCRIPTION OFGOODS | M10: CY | N10: REMARKS | P10: Booking No | Q10: Shipper | R10: SALES/ MKT
A11: 1 | B11: SGSIN | C11: VNHPH | D11: HACT | E11: ONE | F11: DRYU6018669 | G11: VN58476AQ | H11: 06-02-86 | I11: F | J11: 40HC | K11: 15.6643 | L11: PRINTER OR TYPEWRITER CARTRIDGES & RIBBONS | M11: SAO A | P11: HANG16054600 | Q11: ONE | S11: {=[3]!checkcont(F11)} -> #NAME? | T11: =I11&J11 -> F40HC
A12: 2 | B12: SGSIN | C12: VNHPH | D12: HACT | E12: ONE | F12: TRHU4799213 | G12: VN69471AP | H12: 06-01-86 | I12: F | J12: 40HC | K12: 10.71122 | L12: GDSM (GENERAL DEPARTMENT STORE MERCHANDISE) | M12: NHDV | P12: HANG20479500 | Q12: ONE | S12: {=[3]!checkcont(F12)} -> #NAME? | T12: =I12&J12 -> F40HC
A13: 3 | B13: SGSIN | C13: VNHPH | D13: HACT | E13: ONE | F13: FTAU1297613 | G13: VN46959AQ | H13: 17-00-06 | I13: F | J13: 20DC | K13: 25.66 | L13: IRON OR STEEL SCREW,BOLT,NUT,RIVET, OTHER SCREWS AND BOLTS, WHETHER OR NOT WITH THEIR NUTS OR WASHERS | M13: HHH | P13: HANG21869900 | Q13: ONE | S13: {=[3]!checkcont(F13)} -> #NAME? | T13: =I13&J13 -> F20DC
A14: 4 | B14: SGSIN | C14: VNHPH | D14: HACT | E14: ONE | F14: ONEU2623855 | G14: VN46958AQ | H14: 19-06-08 | I14: F | J14: 20DC | K14: 25.66699 | L14: IRON OR STEEL SCREW,BOLT,NUT,RIVET, OTHER SCREWS AND BOLTS, WHETHER OR NOT WITH THEIR NUTS OR WASHERS | M14: HHH | P14: HANG21869900 | Q14: ONE | S14: {=[3]!checkcont(F14)} -> #NAME? | T14: =I14&J14 -> F20DC
A15: 5 | B15: SGSIN | C15: VNHPH | D15: HACT | E15: ONE | F15: KKFU8024007 | G15: vn39269aq | H15: 06-00-86 | I15: F | J15: 40HC | K15: 9.63 | L15: UNIFORMS, APRONS & OTHER GARMENTS, N.O.S., OF MANMADE FIBERS, KNITTED OR CROCHETED | M15: NHDV | P15: HANG23134300 | Q15: ONE | S15: {=[3]!checkcont(F15)} -> #NAME? | T15: =I15&J15 -> F40HC
A16: 6 | B16: SGSIN | C16: VNHPH | D16: HACT | E16: ONE | F16: GAOU6571498 | G16: VN52465AQ | H16: 26-02-06 | I16: F | J16: 40HC | K16: 21.39048 | L16: BAGS & SACKS, OF POLYETHYLENE | M16: HHH | P16: HANG23214900 | Q16: ONE | S16: {=[3]!checkcont(F16)} -> #NAME? | T16: =I16&J16 -> F40HC
A17: 7 | B17: SGSIN | C17: VNHPH | D17: HACT | E17: ONE | F17: KKFU8081584 | G17: VN03637AQ | H17: 26-05-06 | I17: F | J17: 40HC | K17: 28.95758 | L17: BAGS & SACKS, OF POLYETHYLENE | M17: HHH | P17: HANG23214900 | Q17: ONE | S17: {=[3]!checkcont(F17)} -> #NAME? | T17: =I17&J17 -> F40HC
A18: 8 | B18: SGSIN | C18: VNHPH | D18: HACT | E18: ONE | F18: ONEU0038086 | G18: VN52498AQ | H18: 18-05-10 | I18: F | J18: 40HC | K18: 28.93575 | L18: BAGS & SACKS, OF POLYETHYLENE | M18: HHH | P18: HANG23214900 | Q18: ONE | S18: {=[3]!checkcont(F18)} -> #NAME? | T18: =I18&J18 -> F40HC
A19: 9 | B19: SGSIN | C19: VNHPH | D19: HACT | E19: ONE | F19: TCLU7908019 | G19: VN03573AQ | H19: 26-07-08 | I19: F | J19: 40HC | K19: 28.92652 | L19: BAGS & SACKS, OF POLYETHYLENE | M19: HHH | P19: HANG23214900 | Q19: ONE | S19: {=[3]!checkcont(F19)} -> #NAME? | T19: =I19&J19 -> F40HC
A20: 10 | B20: SGSIN | C20: VNHPH | D20: HACT | E20: ONE | F20: BMOU1505128 | G20: VN25747AQ | H20: 17-07-08 | I20: F | J20: 20DC | K20: 22.25 | L20: MOLYBDENUM OXIDES & HYDROXIDES (NON-FERROUS) | M20: HHH | P20: HANG24094900 | Q20: ONE | S20: {=[3]!checkcont(F20)} -> #NAME? | T20: =I20&J20 -> F20DC
A21: 11 | B21: SGSIN | C21: VNHPH | D21: HACT | E21: ONE | F21: ONEU1378856 | G21: VN12801AQ | H21: 18-02-84 | I21: F | J21: 40HC | K21: 12.77303 | L21: CONSOLIDATED CARGO | M21: NHDV | N21: Lithium (Ion/Metal) & Sodium Ion Batteries - On Deck away from Heat | P21: HANG25567800 | Q21: ONE | S21: {=[3]!checkcont(F21)} -> #NAME? | T21: =I21&J21 -> F40HC
A22: 12 | B22: SGSIN | C22: VNHPH | D22: HACT | E22: ONE | F22: TGBU3189110 | G22: VN25542AQ | H22: 27-01-10 | I22: F | J22: 20DC | K22: 4.6824 | L22: PARTS FOR ENGINES & MOTORS | M22: SAO A | P22: HANG25918800 | Q22: ONE | S22: {=[3]!checkcont(F22)} -> #NAME? | T22: =I22&J22 -> F20DC
A23: 13 | B23: SGSIN | C23: VNHPH | D23: HACT | E23: ONE | F23: TLLU6119210 | G23: VN27302AQ | H23: 32-00-88 | I23: F | J23: 40DC | K23: 6.33928 | L23: ATHLETIC FOOTWEAR & SPORTS FOOTWEAR, OF TEXTILE MATERIALS | M23: NHDV | P23: HANG25993400 | Q23: ONE | S23: {=[3]!checkcont(F23)} -> #NAME? | T23: =I23&J23 -> F40DC
A24: 14 | B24: SGSIN | C24: VNHPH | D24: HACT | E24: ONE | F24: ONEU1052936 | G24: VN46767AQ | H24: 06-08-86 | I24: F | J24: 40HC | K24: 10.20531 | L24: COATS, CAPES & CLOAKS FOR MEN & BOYS, OF COTTON, KNITTED OR CROCHETED | M24: SAO A | P24: HANG27388400 | Q24: ONE | S24: {=[3]!checkcont(F24)} -> #NAME? | T24: =I24&J24 -> F40HC
A25: 15 | B25: SGSIN | C25: VNHPH | D25: HACT | E25: ONE | F25: TCKU7216918 | G25: VN46890AQ | H25: 06-06-88 | I25: F | J25: 40HC | K25: 11.058 | L25: LOCKS FOR MOTOR VEHICLES | M25: SAO A | P25: HANG27903400 | Q25: ONE | S25: {=[3]!checkcont(F25)} -> #NAME? | T25: =I25&J25 -> F40HC
A26: 16 | B26: SGSIN | C26: VNHPH | D26: HACT | E26: ONE | F26: NYKU8482839 | G26: VN76451AP | H26: 06-08-88 | I26: F | J26: 40DC | K26: 8.54166 | L26: FAK OR CARGO, NOS | M26: NHDV | P26: HANG28081900 | Q26: ONE | S26: {=[3]!checkcont(F26)} -> #NAME? | T26: =I26&J26 -> F40DC
A27: 17 | B27: SGSIN | C27: VNHPH | D27: HACT | E27: ONE | F27: TRHU6083892 | G27: 46885AQ | H27: 18-02-86 | I27: F | J27: 40HC | K27: 10.03 | L27: SPEAKER,MICRO/HEADPHONE,AMPLIFIER, OTHER | M27: SITC | N27: Lithium (Ion/Metal) & Sodium Ion Batteries - On Deck away from Heat | P27: HANG28420600 | Q27: ONE | S27: {=[3]!checkcont(F27)} -> #NAME? | T27: =I27&J27 -> F40HC
A28: 18 | B28: SGSIN | C28: VNHPH | D28: HACT | E28: ONE | F28: TEMU7306744 | G28: 50147AQ | H28: 18-09-86 | I28: F | J28: 40HC | K28: 10.078 | L28: MOTORCYCLES | M28: SITC | P28: HANG28461400 | Q28: ONE | S28: {=[3]!checkcont(F28)} -> #NAME? | T28: =I28&J28 -> F40HC
A29: 19 | B29: SGSIN | C29: VNHPH | D29: HACT | E29: ONE | F29: TLLU4818476 | G29: 50143AQ | H29: 18-10-88 | I29: F | J29: 40HC | K29: 9.888 | L29: MOTORCYCLES | M29: SITC | P29: HANG28461400 | Q29: ONE | S29: {=[3]!checkcont(F29)} -> #NAME? | T29: =I29&J29 -> F40HC
A30: 20 | B30: SGSIN | C30: VNHPH | D30: HACT | E30: ONE | F30: TRHU4597110 | G30: 50138A | H30: 06-05-88 | I30: F | J30: 40HC | K30: 9.888 | L30: MOTORCYCLES | M30: SITC | P30: HANG28461400 | Q30: ONE | S30: {=[3]!checkcont(F30)} -> #NAME? | T30: =I30&J30 -> F40HC
A31: 21 | B31: SGSIN | C31: VNHPH | D31: HACT | E31: ONE | F31: TCNU6122526 | G31: 50104A | H31: 06-03-86 | I31: F | J31: 40HC | K31: 9.998 | L31: MOTORCYCLES | M31: SITC | P31: HANG28464700 | Q31: ONE | S31: {=[3]!checkcont(F31)} -> #NAME? | T31: =I31&J31 -> F40HC
A32: 22 | B32: SGSIN | C32: VNHPH | D32: HACT | E32: ONE | F32: TGCU0011010 | G32: 50131A | H32: 18-10-86 | I32: F | J32: 40HC | K32: 9.958 | L32: MOTORCYCLES | M32: SITC | P32: HANG28464700 | Q32: ONE | S32: {=[3]!checkcont(F32)} -> #NAME? | T32: =I32&J32 -> F40HC
A33: 23 | B33: SGSIN | C33: VNHPH | D33: HACT | E33: ONE | F33: NYKU5152448 | G33: 85447AP | H33: 18-05-84 | I33: F | J33: 40HC | K33: 12.134 | L33: SPEAKER,MICRO/HEADPHONE,AMPLIFIER, OTHER | M33: SITC | P33: HANG28516500 | Q33: ONE | S33: {=[3]!checkcont(F33)} -> #NAME? | T33: =I33&J33 -> F40HC
A34: 24 | B34: SGSIN | C34: VNHPH | D34: HACT | E34: ONE | F34: MOFU0640950 | G34: VN56405AP | H34: 18-01-10 | I34: F | J34: 40DC | K34: 24.62 | L34: PARTS FOR WASHING & LAUNDRY MACHINES | M34: NHDV | P34: HANG28754900 | Q34: ONE | S34: {=[3]!checkcont(F34)} -> #NAME? | T34: =I34&J34 -> F40DC
A35: 25 | B35: SGSIN | C35: VNHPH | D35: HACT | E35: ONE | F35: CAAU9241902 | G35: VN52350AQ | H35: 26-06-86 | I35: F | J35: 40HC | K35: 9.848 | L35: MOTORCYCLES | M35: HHH | P35: HANG28861800 | Q35: ONE | S35: {=[3]!checkcont(F35)} -> #NAME? | T35: =I35&J35 -> F40HC
A36: 26 | B36: SGSIN | C36: VNHPH | D36: HACT | E36: ONE | F36: GAOU6566110 | G36: VN65296AP | H36: 26-03-84 | I36: F | J36: 40HC | K36: 9.878 | L36: MOTORCYCLES | M36: HHH | P36: HANG28861800 | Q36: ONE | S36: {=[3]!checkcont(F36)} -> #NAME? | T36: =I36&J36 -> F40HC
A37: 27 | B37: SGSIN | C37: VNHPH | D37: HACT | E37: ONE | F37: NYKU4754498 | G37: VN65344AP | H37: 18-10-84 | I37: F | J37: 40HC | K37: 9.978 | L37: MOTORCYCLES | M37: HHH | P37: HANG28861800 | Q37: ONE | S37: {=[3]!checkcont(F37)} -> #NAME? | T37: =I37&J37 -> F40HC
A38: 28 | B38: SGSIN | C38: VNHPH | D38: HACT | E38: ONE | F38: TGBU9687552 | G38: VN52478AQ | H38: 26-02-82 | I38: F | J38: 40HC | K38: 9.848 | L38: MOTORCYCLES | M38: HHH | P38: HANG28861800 | Q38: ONE | S38: {=[3]!checkcont(F38)} -> #NAME? | T38: =I38&J38 -> F40HC
A39: 29 | B39: SGSIN | C39: VNHPH | D39: HACT | E39: ONE | F39: TCLU3343001 | G39: vn39270aq | H39: 17-00-86 | I39: F | J39: 20DC | K39: 3.98 | L39: STATIC CONVERTERS | M39: NHDV | P39: HANG28909400 | Q39: ONE | S39: {=[3]!checkcont(F39)} -> #NAME? | T39: =I39&J39 -> F20DC
... A50: 40 | B50: SGSIN | C50: VNHPH | D50: HACT | E50: ONE | F50: TEMU8819850 | G50: 09595A | H50: 26-06-82 | I50: F | J50: 40HC | K50: 11.84264 | L50: PARTS FOR MOTORCYCLES OR MOPEDS | M50: SITC | P50: HANG30358900 | Q50: ONE | S50: {=[3]!checkcont(F50)} -> #NAME? | T50: =I50&J50 -> F40HC
A51: 41 | B51: SGSIN | C51: VNHPH | D51: HACT | E51: ONE | F51: ONEU6401687 | G51: VN53756AP | H51: 18-04-86 | I51: F | J51: 40HC | K51: 9.82 | L51: SPEAKER,MICRO/HEADPHONE,AMPLIFIER, OTHER | M51: HHH | N51: Lithium (Ion/Metal) & Sodium Ion Batteries - On Deck away from Heat | P51: HANG30578600 | Q51: ONE | S51: {=[3]!checkcont(F51)} -> #NAME? | T51: =I51&J51 -> F40HC
A52: 42 | B52: SGSIN | C52: VNHPH | D52: HACT | E52: ONE | F52: TRHU6978964 | G52: VN52269AQ | H52: 26-08-06 | I52: F | J52: 40HC | K52: 26 | L52: WHEELS & RIMS, MOTOR VEHICLE OR TRACTOR | M52: SAO A | P52: HANG30756401 | Q52: ONE | S52: {=[3]!checkcont(F52)} -> #NAME? | T52: =I52&J52 -> F40HC
...

Sheet VICT LADEN
A1: FINAL LIST OF LOADING CONTAINERS
A2: VESSEL: | C2: =TOTAL!E2 -> 0 | H2: PORT OF LOADING : HAI PHONG
A3: VOY: | B3: =+TOTAL!D3 -> 037S | D3: ATA: | E3: =+TOTAL!H3:I3 -> #VALUE! | H3: PORT OF DISCHARGING : DA NANG
A4: FLAG: | B4: =TOTAL!D4:E4 -> #VALUE! | D4: ATD: | E4: =+TOTAL!H4:I4 -> #VALUE! | H4: SHIPPING AGENT : HAIAN AGENCY & LOGISTICS COMPANY LIMITED
A6: HAI AN AGENCY & LOGISTICS CO.,LTD | J6: VICT
A7: 2nd FLOOR HA BUILDING - KM2 DINH VU ROAD - HA DIST - HAI PHONG
A8: TEL : +84-31-3260446 FAX : +84-31-3260577
A10: SQ | B10: OPR | C10: LINE | D10: CONTNo. | E10: SEALNo. | F10: CELL | G10: F | H10: SIZE | I10: VGM (KGM) | J10: DESCRIPTION OFGOODS | K10: CY | L10: REMARKS | M10: Booking No | N10: B/L | O10: Shipper | Q10: CONNECTING VESSEL | R10: POD
A11: 1 | S11: {=[3]!checkcont(D11)} -> Please input data ! | T11: =G11&H11
A12: 2 | S12: {=[3]!checkcont(D12)} -> Please input data ! | T12: =G12&H12
A13: 3 | S13: {=[3]!checkcont(D13)} -> Please input data ! | T13: =G13&H13
A14: 4 | S14: {=[3]!checkcont(D14)} -> Please input data ! | T14: =G14&H14
A15: 5 | S15: {=[3]!checkcont(D15)} -> Please input data ! | T15: =G15&H15
A16: 6 | S16: {=[3]!checkcont(D16)} -> Please input data ! | T16: =G16&H16
A17: 7 | S17: {=[3]!checkcont(D17)} -> Please input data ! | T17: =G17&H17
A18: 8 | S18: {=[3]!checkcont(D18)} -> Please input data ! | T18: =G18&H18
A19: 9 | S19: {=[3]!checkcont(D19)} -> Please input data ! | T19: =G19&H19
A20: 10 | S20: {=[3]!checkcont(D20)} -> Please input data ! | T20: =G20&H20
A21: 11 | S21: {=[3]!checkcont(D21)} -> Please input data ! | T21: =G21&H21
A22: 12 | S22: {=[3]!checkcont(D22)} -> Please input data ! | T22: =G22&H22
... A501: 491 | S501: {=[3]!checkcont(D501)} -> Please input data ! | T501: =G501&H501

Sheet VICT EMPTY
A1: FINAL LIST OF LOADING CONTAINERS
A2: VESSEL: | C2: =+TOTAL!E2 -> 0 | H2: PORT OF LOADING : HAI PHONG
A3: VOY: | B3: =+TOTAL!D3 -> 037S | D3: ATA: | E3: =+TOTAL!#REF! -> #REF! | H3: PORT OF DISCHARGING : HO CHI MINH
A4: FLAG: | B4: =+TOTAL!D4:E4 -> #VALUE! | D4: ATD: | E4: =+TOTAL!#REF! -> #REF! | H4: SHIPPING AGENT : HAIAN AGENCY & LOGISTICS COMPANY LIMITED
A6: HAI AN AGENCY & LOGISTICS CO.,LTD | K6: VICT
A7: 2nd FLOOR HA BUILDING - KM2 DINH VU ROAD - HA DIST - HAI PHONG
A8: TEL : +84-31-3260446 FAX : +84-31-3260577
A10: SQ | B10: OPR | C10: LINE | D10: CONTNo. | E10: CELL | F10: E | G10: SIZE | H10: VGM (KGM) | I10: DESCRIPTION OFGOODS | J10: CY | K10: REMARKS | L10: Booking No | M10: Shipper | N10: SALES/ MKT
A11: 1 | O11: {=[3]!checkcont(D11)} -> Please input data ! | P11: =F11&LEFT(G11,2)
A12: 2 | O12: {=[3]!checkcont(D12)} -> Please input data ! | P12: =F12&LEFT(G12,2)
A13: 3 | O13: {=[3]!checkcont(D13)} -> Please input data ! | P13: =F13&LEFT(G13,2)
A14: 4 | O14: {=[3]!checkcont(D14)} -> Please input data ! | P14: =F14&LEFT(G14,2)
A15: 5 | O15: {=[3]!checkcont(D15)} -> Please input data ! | P15: =F15&LEFT(G15,2)
A16: 6 | O16: {=[3]!checkcont(D16)} -> Please input data ! | P16: =F16&LEFT(G16,2)
A17: 7 | O17: {=[3]!checkcont(D17)} -> Please input data ! | P17: =F17&LEFT(G17,2)
A18: 8 | O18: {=[3]!checkcont(D18)} -> Please input data ! | P18: =F18&LEFT(G18,2)
A19: 9 | O19: {=[3]!checkcont(D19)} -> Please input data ! | P19: =F19&LEFT(G19,2)
A20: 10 | O20: {=[3]!checkcont(D20)} -> Please input data ! | P20: =F20&LEFT(G20,2)
A21: 11 | O21: {=[3]!checkcont(D21)} -> Please input data ! | P21: =F21&LEFT(G21,2)
A22: 12 | O22: {=[3]!checkcont(D22)} -> Please input data ! | P22: =F22&LEFT(G22,2)
... A410: 400 | O410: {=[3]!checkcont(D410)} -> Please input data ! | P410: =F410&LEFT(G410,2)
O411: {=[3]!checkcont(D411)} -> Please input data ! | P411: =F411&LEFT(G411,2)

Sheet BRAVO
A1: POD | B1: LINE | C1: CONTNo. | D1: SEALNo. | E1: CELL | F1: F | G1: SIZE | H1: VGM (KGM) | I1: DESCRIPTION OFGOODS | J1: Booking No | K1: REMARKS | L1: Shipper
A2: TCIT-VUT | B2: =#REF! -> #REF! | C2: =#REF! -> #REF! | D2: =#REF! -> #REF! | E2: =#REF! -> #REF! | F2: =#REF! -> #REF! | G2: =#REF! -> #REF! | H2: =#REF! -> #REF! | I2: =#REF! -> #REF! | ... L2: =#REF! -> #REF!
A3: TCIT-VUT | B3: =#REF! -> #REF! | C3: =#REF! -> #REF! | D3: =#REF! -> #REF! | E3: =#REF! -> #REF! | F3: =#REF! -> #REF! | G3: =#REF! -> #REF! | H3: =#REF! -> #REF! | I3: =#REF! -> #REF! | ... L3: =#REF! -> #REF!
A4: TCIT-VUT | B4: =#REF! -> #REF! | C4: =#REF! -> #REF! | D4: =#REF! -> #REF! | E4: =#REF! -> #REF! | F4: =#REF! -> #REF! | G4: =#REF! -> #REF! | H4: =#REF! -> #REF! | I4: =#REF! -> #REF! | ... L4: =#REF! -> #REF!
A5: TCIT-VUT | B5: =#REF! -> #REF! | C5: =#REF! -> #REF! | D5: =#REF! -> #REF! | E5: =#REF! -> #REF! | F5: =#REF! -> #REF! | G5: =#REF! -> #REF! | H5: =#REF! -> #REF! | I5: =#REF! -> #REF! | ... L5: =#REF! -> #REF!
A6: TCIT-VUT | B6: =#REF! -> #REF! | C6: =#REF! -> #REF! | D6: =#REF! -> #REF! | E6: =#REF! -> #REF! | F6: =#REF! -> #REF! | G6: =#REF! -> #REF! | H6: =#REF! -> #REF! | I6: =#REF! -> #REF! | ... L6: =#REF! -> #REF!
A7: TCIT-VUT | B7: =#REF! -> #REF! | C7: =#REF! -> #REF! | D7: =#REF! -> #REF! | E7: =#REF! -> #REF! | F7: =#REF! -> #REF! | G7: =#REF! -> #REF! | H7: =#REF! -> #REF! | I7: =#REF! -> #REF! | ... L7: =#REF! -> #REF!
A8: TCIT-VUT | B8: =#REF! -> #REF! | C8: =#REF! -> #REF! | D8: =#REF! -> #REF! | E8: =#REF! -> #REF! | F8: =#REF! -> #REF! | G8: =#REF! -> #REF! | H8: =#REF! -> #REF! | I8: =#REF! -> #REF! | ... L8: =#REF! -> #REF!
A9: TCIT-VUT | B9: =#REF! -> #REF! | C9: =#REF! -> #REF! | D9: =#REF! -> #REF! | E9: =#REF! -> #REF! | F9: =#REF! -> #REF! | G9: =#REF! -> #REF! | H9: =#REF! -> #REF! | I9: =#REF! -> #REF! | ... L9: =#REF! -> #REF!
A10: TCIT-VUT | B10: =#REF! -> #REF! | C10: =#REF! -> #REF! | D10: =#REF! -> #REF! | E10: =#REF! -> #REF! | F10: =#REF! -> #REF! | G10: =#REF! -> #REF! | H10: =#REF! -> #REF! | I10: =#REF! -> #REF! | ... L10: =#REF! -> #REF!
A11: TCIT-VUT | B11: =#REF! -> #REF! | C11: =#REF! -> #REF! | D11: =#REF! -> #REF! | E11: =#REF! -> #REF! | F11: =#REF! -> #REF! | G11: =#REF! -> #REF! | H11: =#REF! -> #REF! | I11: =#REF! -> #REF! | ... L11: =#REF! -> #REF!
A12: TCIT-VUT | B12: =#REF! -> #REF! | C12: =#REF! -> #REF! | D12: =#REF! -> #REF! | E12: =#REF! -> #REF! | F12: =#REF! -> #REF! | G12: =#REF! -> #REF! | H12: =#REF! -> #REF! | I12: =#REF! -> #REF! | ... L12: =#REF! -> #REF!
A13: TCIT-VUT | B13: =#REF! -> #REF! | C13: =#REF! -> #REF! | D13: =#REF! -> #REF! | E13: =#REF! -> #REF! | F13: =#REF! -> #REF! | G13: =#REF! -> #REF! | H13: =#REF! -> #REF! | I13: =#REF! -> #REF! | ... L13: =#REF! -> #REF!
... A501: TCIT-VUT | B501: =#REF! -> #REF! | C501: =#REF! -> #REF! | D501: =#REF! -> #REF! | E501: =#REF! -> #REF! | F501: =#REF! -> #REF! | G501: =#REF! -> #REF! | H501: =#REF! -> #REF! | I501: =#REF! -> #REF! | ... L501: =#REF! -> #REF!
A502: VICT | B502: ='VICT EMPTY'!C11 -> 0 | C502: ='VICT EMPTY'!D11 -> 0 | D502: ='VICT LADEN'!E11 -> 0 | E502: ='VICT EMPTY'!E11 -> 0 | F502: ='VICT EMPTY'!F11 -> 0 | G502: ='VICT EMPTY'!G11 -> 0 | H502: ='VICT EMPTY'!H11 -> 0 | I502: ='VICT EMPTY'!I11 -> 0 | J502: ='VICT EMPTY'!L11 -> 0 | K502: ='VICT EMPTY'!K11 -> 0 | L502: ='VICT EMPTY'!M11 -> 0
A503: VICT | B503: ='VICT EMPTY'!C12 -> 0 | C503: ='VICT EMPTY'!D12 -> 0 | D503: ='VICT LADEN'!E12 -> 0 | E503: ='VICT EMPTY'!E12 -> 0 | F503: ='VICT EMPTY'!F12 -> 0 | G503: ='VICT EMPTY'!G12 -> 0 | H503: ='VICT EMPTY'!H12 -> 0 | I503: ='VICT EMPTY'!I12 -> 0 | J503: ='VICT EMPTY'!L12 -> 0 | K503: ='VICT EMPTY'!K12 -> 0 | L503: ='VICT EMPTY'!M12 -> 0
A504: VICT | B504: ='VICT EMPTY'!C13 -> 0 | C504: ='VICT EMPTY'!D13 -> 0 | D504: ='VICT LADEN'!E13 -> 0 | E504: ='VICT EMPTY'!E13 -> 0 | F504: ='VICT EMPTY'!F13 -> 0 | G504: ='VICT EMPTY'!G13 -> 0 | H504: ='VICT EMPTY'!H13 -> 0 | I504: ='VICT EMPTY'!I13 -> 0 | J504: ='VICT EMPTY'!L13 -> 0 | K504: ='VICT EMPTY'!K13 -> 0 | L504: ='VICT EMPTY'!M13 -> 0
A505: VICT | B505: ='VICT EMPTY'!C14 -> 0 | C505: ='VICT EMPTY'!D14 -> 0 | D505: ='VICT LADEN'!E14 -> 0 | E505: ='VICT EMPTY'!E14 -> 0 | F505: ='VICT EMPTY'!F14 -> 0 | G505: ='VICT EMPTY'!G14 -> 0 | H505: ='VICT EMPTY'!H14 -> 0 | I505: ='VICT EMPTY'!I14 -> 0 | J505: ='VICT EMPTY'!L14 -> 0 | K505: ='VICT EMPTY'!K14 -> 0 | L505: ='VICT EMPTY'!M14 -> 0
A506: VICT | B506: ='VICT EMPTY'!C15 -> 0 | C506: ='VICT EMPTY'!D15 -> 0 | D506: ='VICT LADEN'!E15 -> 0 | E506: ='VICT EMPTY'!E15 -> 0 | F506: ='VICT EMPTY'!F15 -> 0 | G506: ='VICT EMPTY'!G15 -> 0 | H506: ='VICT EMPTY'!H15 -> 0 | I506: ='VICT EMPTY'!I15 -> 0 | J506: ='VICT EMPTY'!L15 -> 0 | K506: ='VICT EMPTY'!K15 -> 0 | L506: ='VICT EMPTY'!M15 -> 0
A507: VICT | B507: ='VICT EMPTY'!C16 -> 0 | C507: ='VICT EMPTY'!D16 -> 0 | D507: ='VICT LADEN'!E16 -> 0 | E507: ='VICT EMPTY'!E16 -> 0 | F507: ='VICT EMPTY'!F16 -> 0 | G507: ='VICT EMPTY'!G16 -> 0 | H507: ='VICT EMPTY'!H16 -> 0 | I507: ='VICT EMPTY'!I16 -> 0 | J507: ='VICT EMPTY'!L16 -> 0 | K507: ='VICT EMPTY'!K16 -> 0 | L507: ='VICT EMPTY'!M16 -> 0
A508: VICT | B508: ='VICT EMPTY'!C17 -> 0 | C508: ='VICT EMPTY'!D17 -> 0 | D508: ='VICT LADEN'!E17 -> 0 | E508: ='VICT EMPTY'!E17 -> 0 | F508: ='VICT EMPTY'!F17 -> 0 | G508: ='VICT EMPTY'!G17 -> 0 | H508: ='VICT EMPTY'!H17 -> 0 | I508: ='VICT EMPTY'!I17 -> 0 | J508: ='VICT EMPTY'!L17 -> 0 | K508: ='VICT EMPTY'!K17 -> 0 | L508: ='VICT EMPTY'!M17 -> 0
A509: VICT | B509: ='VICT EMPTY'!C18 -> 0 | C509: ='VICT EMPTY'!D18 -> 0 | D509: ='VICT LADEN'!E18 -> 0 | E509: ='VICT EMPTY'!E18 -> 0 | F509: ='VICT EMPTY'!F18 -> 0 | G509: ='VICT EMPTY'!G18 -> 0 | H509: ='VICT EMPTY'!H18 -> 0 | I509: ='VICT EMPTY'!I18 -> 0 | J509: ='VICT EMPTY'!L18 -> 0 | K509: ='VICT EMPTY'!K18 -> 0 | L509: ='VICT EMPTY'!M18 -> 0
A510: VICT | B510: ='VICT EMPTY'!C19 -> 0 | C510: ='VICT EMPTY'!D19 -> 0 | D510: ='VICT LADEN'!E19 -> 0 | E510: ='VICT EMPTY'!E19 -> 0 | F510: ='VICT EMPTY'!F19 -> 0 | G510: ='VICT EMPTY'!G19 -> 0 | H510: ='VICT EMPTY'!H19 -> 0 | I510: ='VICT EMPTY'!I19 -> 0 | J510: ='VICT EMPTY'!L19 -> 0 | K510: ='VICT EMPTY'!K19 -> 0 | L510: ='VICT EMPTY'!M19 -> 0
A511: VICT | B511: ='VICT EMPTY'!C20 -> 0 | C511: ='VICT EMPTY'!D20 -> 0 | D511: ='VICT LADEN'!E20 -> 0 | E511: ='VICT EMPTY'!E20 -> 0 | F511: ='VICT EMPTY'!F20 -> 0 | G511: ='VICT EMPTY'!G20 -> 0 | H511: ='VICT EMPTY'!H20 -> 0 | I511: ='VICT EMPTY'!I20 -> 0 | J511: ='VICT EMPTY'!L20 -> 0 | K511: ='VICT EMPTY'!K20 -> 0 | L511: ='VICT EMPTY'!M20 -> 0
A512: VICT | B512: ='VICT EMPTY'!C21 -> 0 | C512: ='VICT EMPTY'!D21 -> 0 | D512: ='VICT LADEN'!E21 -> 0 | E512: ='VICT EMPTY'!E21 -> 0 | F512: ='VICT EMPTY'!F21 -> 0 | G512: ='VICT EMPTY'!G21 -> 0 | H512: ='VICT EMPTY'!H21 -> 0 | I512: ='VICT EMPTY'!I21 -> 0 | J512: ='VICT EMPTY'!L21 -> 0 | K512: ='VICT EMPTY'!K21 -> 0 | L512: ='VICT EMPTY'!M21 -> 0
A513: VICT | B513: ='VICT EMPTY'!C22 -> 0 | C513: ='VICT EMPTY'!D22 -> 0 | D513: ='VICT LADEN'!E22 -> 0 | E513: ='VICT EMPTY'!E22 -> 0 | F513: ='VICT EMPTY'!F22 -> 0 | G513: ='VICT EMPTY'!G22 -> 0 | H513: ='VICT EMPTY'!H22 -> 0 | I513: ='VICT EMPTY'!I22 -> 0 | J513: ='VICT EMPTY'!L22 -> 0 | K513: ='VICT EMPTY'!K22 -> 0 | L513: ='VICT EMPTY'!M22 -> 0
... A603: VICT | B603: ='VICT EMPTY'!C112 -> 0 | C603: ='VICT EMPTY'!D112 -> 0 | D603: ='VICT LADEN'!E112 -> 0 | E603: ='VICT EMPTY'!E112 -> 0 | F603: ='VICT EMPTY'!F112 -> 0 | G603: ='VICT EMPTY'!G112 -> 0 | H603: ='VICT EMPTY'!H112 -> 0 | I603: ='VICT EMPTY'!I112 -> 0 | J603: ='VICT EMPTY'!L112 -> 0 | K603: ='VICT EMPTY'!K112 -> 0 | L603: ='VICT EMPTY'!M112 -> 0
A604: TIENSA | B604: ='VICT LADEN'!C104 -> 0 | C604: ='VICT LADEN'!D104 -> 0 | D604: ='VICT LADEN'!E104 -> 0 | E604: ='VICT LADEN'!F104 -> 0 | F604: ='VICT LADEN'!G104 -> 0 | G604: ='VICT LADEN'!H104 -> 0 | H604: ='VICT LADEN'!I104 -> 0 | I604: ='VICT LADEN'!J104 -> 0 | J604: ='VICT LADEN'!O104 -> 0 | K604: ='VICT LADEN'!L104 -> 0 | L604: ='VICT LADEN'!P104 -> 0
A605: TIENSA | B605: ='VICT LADEN'!C105 -> 0 | C605: ='VICT LADEN'!D105 -> 0 | D605: ='VICT LADEN'!E105 -> 0 | E605: ='VICT LADEN'!F105 -> 0 | F605: ='VICT LADEN'!G105 -> 0 | G605: ='VICT LADEN'!H105 -> 0 | H605: ='VICT LADEN'!I105 -> 0 | I605: ='VICT LADEN'!J105 -> 0 | J605: ='VICT LADEN'!O105 -> 0 | K605: ='VICT LADEN'!L105 -> 0 | L605: ='VICT LADEN'!P105 -> 0
A606: TIENSA | B606: ='VICT LADEN'!C106 -> 0 | C606: ='VICT LADEN'!D106 -> 0 | D606: ='VICT LADEN'!E106 -> 0 | E606: ='VICT LADEN'!F106 -> 0 | F606: ='VICT LADEN'!G106 -> 0 | G606: ='VICT LADEN'!H106 -> 0 | H606: ='VICT LADEN'!I106 -> 0 | I606: ='VICT LADEN'!J106 -> 0 | J606: ='VICT LADEN'!O106 -> 0 | K606: ='VICT LADEN'!L106 -> 0 | L606: ='VICT LADEN'!P106 -> 0
A607: TIENSA | B607: ='VICT LADEN'!C107 -> 0 | C607: ='VICT LADEN'!D107 -> 0 | D607: ='VICT LADEN'!E107 -> 0 | E607: ='VICT LADEN'!F107 -> 0 | F607: ='VICT LADEN'!G107 -> 0 | G607: ='VICT LADEN'!H107 -> 0 | H607: ='VICT LADEN'!I107 -> 0 | I607: ='VICT LADEN'!J107 -> 0 | J607: ='VICT LADEN'!O107 -> 0 | K607: ='VICT LADEN'!L107 -> 0 | L607: ='VICT LADEN'!P107 -> 0
A608: TIENSA | B608: ='VICT LADEN'!C108 -> 0 | C608: ='VICT LADEN'!D108 -> 0 | D608: ='VICT LADEN'!E108 -> 0 | E608: ='VICT LADEN'!F108 -> 0 | F608: ='VICT LADEN'!G108 -> 0 | G608: ='VICT LADEN'!H108 -> 0 | H608: ='VICT LADEN'!I108 -> 0 | I608: ='VICT LADEN'!J108 -> 0 | J608: ='VICT LADEN'!O108 -> 0 | K608: ='VICT LADEN'!L108 -> 0 | L608: ='VICT LADEN'!P108 -> 0
A609: TIENSA | B609: ='VICT LADEN'!C109 -> 0 | C609: ='VICT LADEN'!D109 -> 0 | D609: ='VICT LADEN'!E109 -> 0 | E609: ='VICT LADEN'!F109 -> 0 | F609: ='VICT LADEN'!G109 -> 0 | G609: ='VICT LADEN'!H109 -> 0 | H609: ='VICT LADEN'!I109 -> 0 | I609: ='VICT LADEN'!J109 -> 0 | J609: ='VICT LADEN'!O109 -> 0 | K609: ='VICT LADEN'!L109 -> 0 | L609: ='VICT LADEN'!P109 -> 0
A610: TIENSA | B610: ='VICT LADEN'!C110 -> 0 | C610: ='VICT LADEN'!D110 -> 0 | D610: ='VICT LADEN'!E110 -> 0 | E610: ='VICT LADEN'!F110 -> 0 | F610: ='VICT LADEN'!G110 -> 0 | G610: ='VICT LADEN'!H110 -> 0 | H610: ='VICT LADEN'!I110 -> 0 | I610: ='VICT LADEN'!J110 -> 0 | J610: ='VICT LADEN'!O110 -> 0 | K610: ='VICT LADEN'!L110 -> 0 | L610: ='VICT LADEN'!P110 -> 0
A611: TIENSA | B611: ='VICT LADEN'!C111 -> 0 | C611: ='VICT LADEN'!D111 -> 0 | D611: ='VICT LADEN'!E111 -> 0 | E611: ='VICT LADEN'!F111 -> 0 | F611: ='VICT LADEN'!G111 -> 0 | G611: ='VICT LADEN'!H111 -> 0 | H611: ='VICT LADEN'!I111 -> 0 | I611: ='VICT LADEN'!J111 -> 0 | J611: ='VICT LADEN'!O111 -> 0 | K611: ='VICT LADEN'!L111 -> 0 | L611: ='VICT LADEN'!P111 -> 0
A612: TIENSA | B612: ='VICT LADEN'!C112 -> 0 | C612: ='VICT LADEN'!D112 -> 0 | D612: ='VICT LADEN'!E112 -> 0 | E612: ='VICT LADEN'!F112 -> 0 | F612: ='VICT LADEN'!G112 -> 0 | G612: ='VICT LADEN'!H112 -> 0 | H612: ='VICT LADEN'!I112 -> 0 | I612: ='VICT LADEN'!J112 -> 0 | J612: ='VICT LADEN'!O112 -> 0 | K612: ='VICT LADEN'!L112 -> 0 | L612: ='VICT LADEN'!P112 -> 0
A613: TIENSA | B613: ='VICT LADEN'!C113 -> 0 | C613: ='VICT LADEN'!D113 -> 0 | D613: ='VICT LADEN'!E113 -> 0 | E613: ='VICT LADEN'!F113 -> 0 | F613: ='VICT LADEN'!G113 -> 0 | G613: ='VICT LADEN'!H113 -> 0 | H613: ='VICT LADEN'!I113 -> 0 | I613: ='VICT LADEN'!J113 -> 0 | J613: ='VICT LADEN'!O113 -> 0 | K613: ='VICT LADEN'!L113 -> 0 | L613: ='VICT LADEN'!P113 -> 0
A614: TIENSA | B614: ='VICT LADEN'!C114 -> 0 | C614: ='VICT LADEN'!D114 -> 0 | D614: ='VICT LADEN'!E114 -> 0 | E614: ='VICT LADEN'!F114 -> 0 | F614: ='VICT LADEN'!G114 -> 0 | G614: ='VICT LADEN'!H114 -> 0 | H614: ='VICT LADEN'!I114 -> 0 | I614: ='VICT LADEN'!J114 -> 0 | J614: ='VICT LADEN'!O114 -> 0 | K614: ='VICT LADEN'!L114 -> 0 | L614: ='VICT LADEN'!P114 -> 0
A615: TIENSA | B615: ='VICT LADEN'!C115 -> 0 | C615: ='VICT LADEN'!D115 -> 0 | D615: ='VICT LADEN'!E115 -> 0 | E615: ='VICT LADEN'!F115 -> 0 | F615: ='VICT LADEN'!G115 -> 0 | G615: ='VICT LADEN'!H115 -> 0 | H615: ='VICT LADEN'!I115 -> 0 | I615: ='VICT LADEN'!J115 -> 0 | J615: ='VICT LADEN'!O115 -> 0 | K615: ='VICT LADEN'!L115 -> 0 | L615: ='VICT LADEN'!P115 -> 0
... A1001: TIENSA | B1001: ='VICT LADEN'!C501 -> 0 | C1001: ='VICT LADEN'!D501 -> 0 | D1001: ='VICT LADEN'!E501 -> 0 | E1001: ='VICT LADEN'!F501 -> 0 | F1001: ='VICT LADEN'!G501 -> 0 | G1001: ='VICT LADEN'!H501 -> 0 | H1001: ='VICT LADEN'!I501 -> 0 | I1001: ='VICT LADEN'!J501 -> 0 | J1001: ='VICT LADEN'!O501 -> 0 | K1001: ='VICT LADEN'!L501 -> 0 | L1001: ='VICT LADEN'!P501 -> 0
...
