Workbook

Sheet BKTT T4.26
A1: CÔNG TY TNHH AMT PHÚC LỘC
A2: Địa chỉ: Số 56B/97 đường Đoàn Kết , P. Hải An, TP Hải Phòng
A4: BẢNG QUYẾT TOÁN PHÍ VẬN CHUYỂN THÁNG 04/2026
B5: KHÁCH HÀNG: CÔNG TY TNHH PAN HẢI AN
B6: ĐỊA CHỈ: | C6: Lô KB5, khu công nghiệp Nam Đình Vũ (Khu 1), thuộc Khu kinh tế Đình Vũ - Cát Hải, phường Đông Hải, thành phố Hải Phòng, Việt Nam
B7: MST : | C7: 0201815115
A9: STT | B9: Tuyến vận tải | D9: Đơn vị tính | E9: Loại cont | I9: Cộng Số lượng | J9: Đơn giá | K9: Thành tiền | L9: Ghi chú
E10: Hàng | G10: Vỏ
B11: Điểm đi | C11: Điểm đến | E11: 20' | F11: 40'
A12: 1 | B12: PAN HA | C12: HẢI AN | D12: Chuyến | E12: =SUMIFS('SL T4.26'!E$11:E$2017,'SL T4.26'!$J$11:$J$2017,'BKTT T4.26'!$B12,'SL T4.26'!$K$11:$K$2017,'BKTT T4.26'!$C12) -> 332 | F12: =SUMIFS('SL T4.26'!F$11:F$2017,'SL T4.26'!$J$11:$J$2017,'BKTT T4.26'!$B12,'SL T4.26'!$K$11:$K$2017,'BKTT T4.26'!$C12) -> 0 | G12: =SUMIFS('SL T4.26'!G$11:G$2017,'SL T4.26'!$J$11:$J$2017,'BKTT T4.26'!$B12,'SL T4.26'!$K$11:$K$2017,'BKTT T4.26'!$C12)+SUMIFS('SL T4.26'!H$11:H$2017,'SL T4.26'!$J$11:$J$2017,'BKTT T4.26'!$B12,'SL T4.26'!$K$11:$K$2017,'BKTT T4.26'!$C12) -> 0 | I12: =E12+F12+G12+H12 -> 332 | J12: =K12/I12 -> 654871 | K12: =SUMIFS('SL T4.26'!N$11:N$2017,'SL T4.26'!$J$11:$J$2017,'BKTT T4.26'!$B12,'SL T4.26'!$K$11:$K$2017,'BKTT T4.26'!$C12) -> 217417172 | N12: 654871 | O12: =J12-N12 -> 0 | Q12: hàng 20'
A13: 2 | B13: PAN HA | C13: HẢI AN, | D13: Chuyến | E13: =SUMIFS('SL T4.26'!E$11:E$2017,'SL T4.26'!$J$11:$J$2017,'BKTT T4.26'!$B13,'SL T4.26'!$K$11:$K$2017,'BKTT T4.26'!$C13) -> 0 | F13: =SUMIFS('SL T4.26'!F$11:F$2017,'SL T4.26'!$J$11:$J$2017,'BKTT T4.26'!$B13,'SL T4.26'!$K$11:$K$2017,'BKTT T4.26'!$C13) -> 239 | G13: =SUMIFS('SL T4.26'!G$11:G$2017,'SL T4.26'!$J$11:$J$2017,'BKTT T4.26'!$B13,'SL T4.26'!$K$11:$K$2017,'BKTT T4.26'!$C13)+SUMIFS('SL T4.26'!H$11:H$2017,'SL T4.26'!$J$11:$J$2017,'BKTT T4.26'!$B13,'SL T4.26'!$K$11:$K$2017,'BKTT T4.26'!$C13) -> 0 | I13: =E13+F13+G13+H13 -> 239 | J13: =K13/I13 -> 681050 | K13: =SUMIFS('SL T4.26'!N$11:N$2017,'SL T4.26'!$J$11:$J$2017,'BKTT T4.26'!$B13,'SL T4.26'!$K$11:$K$2017,'BKTT T4.26'!$C13) -> 162770950 | N13: 681050 | O13: =J13-N13 -> 0 | Q13: hàng 40'
A14: 3 | B14: PAN HA | C14: HẢI AN. | D14: Chuyến | E14: =SUMIFS('SL T4.26'!E$11:E$2017,'SL T4.26'!$J$11:$J$2017,'BKTT T4.26'!$B14,'SL T4.26'!$K$11:$K$2017,'BKTT T4.26'!$C14) -> 0 | F14: =SUMIFS('SL T4.26'!F$11:F$2017,'SL T4.26'!$J$11:$J$2017,'BKTT T4.26'!$B14,'SL T4.26'!$K$11:$K$2017,'BKTT T4.26'!$C14) -> 0 | G14: =SUMIFS('SL T4.26'!G$11:G$2017,'SL T4.26'!$J$11:$J$2017,'BKTT T4.26'!$B14,'SL T4.26'!$K$11:$K$2017,'BKTT T4.26'!$C14)+SUMIFS('SL T4.26'!H$11:H$2017,'SL T4.26'!$J$11:$J$2017,'BKTT T4.26'!$B14,'SL T4.26'!$K$11:$K$2017,'BKTT T4.26'!$C14) -> 139 | I14: =E14+F14+G14+H14 -> 139 | J14: =K14/I14 -> 628690 | K14: =SUMIFS('SL T4.26'!N$11:N$2017,'SL T4.26'!$J$11:$J$2017,'BKTT T4.26'!$B14,'SL T4.26'!$K$11:$K$2017,'BKTT T4.26'!$C14) -> 87387910 | N14: 628690 | O14: =J14-N14 -> 0 | Q14: Vỏ
A15: 4 | B15: PAN HA | C15: MPC | D15: Chuyến | E15: =SUMIFS('SL T4.26'!E$11:E$2017,'SL T4.26'!$J$11:$J$2017,'BKTT T4.26'!$B15,'SL T4.26'!$K$11:$K$2017,'BKTT T4.26'!$C15) -> 0 | F15: =SUMIFS('SL T4.26'!F$11:F$2017,'SL T4.26'!$J$11:$J$2017,'BKTT T4.26'!$B15,'SL T4.26'!$K$11:$K$2017,'BKTT T4.26'!$C15) -> 0 | G15: =SUMIFS('SL T4.26'!G$11:G$2017,'SL T4.26'!$J$11:$J$2017,'BKTT T4.26'!$B15,'SL T4.26'!$K$11:$K$2017,'BKTT T4.26'!$C15)+SUMIFS('SL T4.26'!H$11:H$2017,'SL T4.26'!$J$11:$J$2017,'BKTT T4.26'!$B15,'SL T4.26'!$K$11:$K$2017,'BKTT T4.26'!$C15) -> 0 | I15: =E15+F15+G15+H15 -> 0 | J15: =K15/I15 -> #DIV/0! | K15: =SUMIFS('SL T4.26'!N$11:N$2017,'SL T4.26'!$J$11:$J$2017,'BKTT T4.26'!$B15,'SL T4.26'!$K$11:$K$2017,'BKTT T4.26'!$C15) -> 0 | N15: 471611 | O15: =J15-N15 -> #DIV/0! | Q15: hàng 20'
A16: 5 | B16: PAN HA | C16: MPC, | D16: Chuyến | E16: =SUMIFS('SL T4.26'!E$11:E$2017,'SL T4.26'!$J$11:$J$2017,'BKTT T4.26'!$B16,'SL T4.26'!$K$11:$K$2017,'BKTT T4.26'!$C16) -> 0 | F16: =SUMIFS('SL T4.26'!F$11:F$2017,'SL T4.26'!$J$11:$J$2017,'BKTT T4.26'!$B16,'SL T4.26'!$K$11:$K$2017,'BKTT T4.26'!$C16) -> 0 | G16: =SUMIFS('SL T4.26'!G$11:G$2017,'SL T4.26'!$J$11:$J$2017,'BKTT T4.26'!$B16,'SL T4.26'!$K$11:$K$2017,'BKTT T4.26'!$C16)+SUMIFS('SL T4.26'!H$11:H$2017,'SL T4.26'!$J$11:$J$2017,'BKTT T4.26'!$B16,'SL T4.26'!$K$11:$K$2017,'BKTT T4.26'!$C16) -> 0 | I16: =E16+F16+G16+H16 -> 0 | J16: =K16/I16 -> #DIV/0! | K16: =SUMIFS('SL T4.26'!N$11:N$2017,'SL T4.26'!$J$11:$J$2017,'BKTT T4.26'!$B16,'SL T4.26'!$K$11:$K$2017,'BKTT T4.26'!$C16) -> 0 | N16: 506518 | O16: =J16-N16 -> #DIV/0! | Q16: hàng 40'
A17: 6 | B17: PAN HA | C17: MPC. | D17: Chuyến | E17: =SUMIFS('SL T4.26'!E$11:E$2017,'SL T4.26'!$J$11:$J$2017,'BKTT T4.26'!$B17,'SL T4.26'!$K$11:$K$2017,'BKTT T4.26'!$C17) -> 0 | F17: =SUMIFS('SL T4.26'!F$11:F$2017,'SL T4.26'!$J$11:$J$2017,'BKTT T4.26'!$B17,'SL T4.26'!$K$11:$K$2017,'BKTT T4.26'!$C17) -> 0 | G17: =SUMIFS('SL T4.26'!G$11:G$2017,'SL T4.26'!$J$11:$J$2017,'BKTT T4.26'!$B17,'SL T4.26'!$K$11:$K$2017,'BKTT T4.26'!$C17)+SUMIFS('SL T4.26'!H$11:H$2017,'SL T4.26'!$J$11:$J$2017,'BKTT T4.26'!$B17,'SL T4.26'!$K$11:$K$2017,'BKTT T4.26'!$C17) -> 3 | I17: =E17+F17+G17+H17 -> 3 | J17: =K17/I17 -> 480338 | K17: =SUMIFS('SL T4.26'!N$11:N$2017,'SL T4.26'!$J$11:$J$2017,'BKTT T4.26'!$B17,'SL T4.26'!$K$11:$K$2017,'BKTT T4.26'!$C17) -> 1441014 | N17: 480338 | O17: =J17-N17 -> 0 | Q17: Vỏ
A18: 7 | B18: PAN HA | C18: NDV | D18: Chuyến | E18: =SUMIFS('SL T4.26'!E$11:E$2017,'SL T4.26'!$J$11:$J$2017,'BKTT T4.26'!$B18,'SL T4.26'!$K$11:$K$2017,'BKTT T4.26'!$C18) -> 86 | F18: =SUMIFS('SL T4.26'!F$11:F$2017,'SL T4.26'!$J$11:$J$2017,'BKTT T4.26'!$B18,'SL T4.26'!$K$11:$K$2017,'BKTT T4.26'!$C18) -> 0 | G18: =SUMIFS('SL T4.26'!G$11:G$2017,'SL T4.26'!$J$11:$J$2017,'BKTT T4.26'!$B18,'SL T4.26'!$K$11:$K$2017,'BKTT T4.26'!$C18)+SUMIFS('SL T4.26'!H$11:H$2017,'SL T4.26'!$J$11:$J$2017,'BKTT T4.26'!$B18,'SL T4.26'!$K$11:$K$2017,'BKTT T4.26'!$C18) -> 0 | I18: =E18+F18+G18+H18 -> 86 | J18: =K18/I18 -> 454158 | K18: =SUMIFS('SL T4.26'!N$11:N$2017,'SL T4.26'!$J$11:$J$2017,'BKTT T4.26'!$B18,'SL T4.26'!$K$11:$K$2017,'BKTT T4.26'!$C18) -> 39057588 | N18: 454158 | O18: =J18-N18 -> 0 | Q18: hàng 20'
A19: 8 | B19: PAN HA | C19: NDV, | D19: Chuyến | E19: =SUMIFS('SL T4.26'!E$11:E$2017,'SL T4.26'!$J$11:$J$2017,'BKTT T4.26'!$B19,'SL T4.26'!$K$11:$K$2017,'BKTT T4.26'!$C19) -> 0 | F19: =SUMIFS('SL T4.26'!F$11:F$2017,'SL T4.26'!$J$11:$J$2017,'BKTT T4.26'!$B19,'SL T4.26'!$K$11:$K$2017,'BKTT T4.26'!$C19) -> 3 | G19: =SUMIFS('SL T4.26'!G$11:G$2017,'SL T4.26'!$J$11:$J$2017,'BKTT T4.26'!$B19,'SL T4.26'!$K$11:$K$2017,'BKTT T4.26'!$C19)+SUMIFS('SL T4.26'!H$11:H$2017,'SL T4.26'!$J$11:$J$2017,'BKTT T4.26'!$B19,'SL T4.26'!$K$11:$K$2017,'BKTT T4.26'!$C19) -> 0 | I19: =E19+F19+G19+H19 -> 3 | J19: =K19/I19 -> 489065 | K19: =SUMIFS('SL T4.26'!N$11:N$2017,'SL T4.26'!$J$11:$J$2017,'BKTT T4.26'!$B19,'SL T4.26'!$K$11:$K$2017,'BKTT T4.26'!$C19) -> 1467195 | N19: 489065 | O19: =J19-N19 -> 0 | Q19: hàng 40'
A20: 9 | B20: PAN HA | C20: NDV. | D20: Chuyến | E20: =SUMIFS('SL T4.26'!E$11:E$2017,'SL T4.26'!$J$11:$J$2017,'BKTT T4.26'!$B20,'SL T4.26'!$K$11:$K$2017,'BKTT T4.26'!$C20) -> 0 | F20: =SUMIFS('SL T4.26'!F$11:F$2017,'SL T4.26'!$J$11:$J$2017,'BKTT T4.26'!$B20,'SL T4.26'!$K$11:$K$2017,'BKTT T4.26'!$C20) -> 0 | G20: =SUMIFS('SL T4.26'!G$11:G$2017,'SL T4.26'!$J$11:$J$2017,'BKTT T4.26'!$B20,'SL T4.26'!$K$11:$K$2017,'BKTT T4.26'!$C20)+SUMIFS('SL T4.26'!H$11:H$2017,'SL T4.26'!$J$11:$J$2017,'BKTT T4.26'!$B20,'SL T4.26'!$K$11:$K$2017,'BKTT T4.26'!$C20) -> 0 | I20: =E20+F20+G20+H20 -> 0 | J20: =K20/I20 -> #DIV/0! | K20: =SUMIFS('SL T4.26'!N$11:N$2017,'SL T4.26'!$J$11:$J$2017,'BKTT T4.26'!$B20,'SL T4.26'!$K$11:$K$2017,'BKTT T4.26'!$C20) -> 0 | O20: =J20-N20 -> #DIV/0! | Q20: Vỏ
A21: 10 | B21: PAN HA | C21: HẢI MINH | D21: Chuyến | E21: =SUMIFS('SL T4.26'!E$11:E$2017,'SL T4.26'!$J$11:$J$2017,'BKTT T4.26'!$B21,'SL T4.26'!$K$11:$K$2017,'BKTT T4.26'!$C21) -> 0 | F21: =SUMIFS('SL T4.26'!F$11:F$2017,'SL T4.26'!$J$11:$J$2017,'BKTT T4.26'!$B21,'SL T4.26'!$K$11:$K$2017,'BKTT T4.26'!$C21) -> 0 | G21: =SUMIFS('SL T4.26'!G$11:G$2017,'SL T4.26'!$J$11:$J$2017,'BKTT T4.26'!$B21,'SL T4.26'!$K$11:$K$2017,'BKTT T4.26'!$C21)+SUMIFS('SL T4.26'!H$11:H$2017,'SL T4.26'!$J$11:$J$2017,'BKTT T4.26'!$B21,'SL T4.26'!$K$11:$K$2017,'BKTT T4.26'!$C21) -> 0 | I21: =E21+F21+G21+H21 -> 0 | J21: =K21/I21 -> #DIV/0! | K21: =SUMIFS('SL T4.26'!N$11:N$2017,'SL T4.26'!$J$11:$J$2017,'BKTT T4.26'!$B21,'SL T4.26'!$K$11:$K$2017,'BKTT T4.26'!$C21) -> 0 | L21: Chuyển bãi | O21: =J21-N21 -> #DIV/0! | Q21: Vỏ
A22: 11 | B22: PAN HA | C22: NHĐV | D22: Chuyến | E22: =SUMIFS('SL T4.26'!E$11:E$2017,'SL T4.26'!$J$11:$J$2017,'BKTT T4.26'!$B22,'SL T4.26'!$K$11:$K$2017,'BKTT T4.26'!$C22) -> 116 | F22: =SUMIFS('SL T4.26'!F$11:F$2017,'SL T4.26'!$J$11:$J$2017,'BKTT T4.26'!$B22,'SL T4.26'!$K$11:$K$2017,'BKTT T4.26'!$C22) -> 0 | G22: =SUMIFS('SL T4.26'!G$11:G$2017,'SL T4.26'!$J$11:$J$2017,'BKTT T4.26'!$B22,'SL T4.26'!$K$11:$K$2017,'BKTT T4.26'!$C22)+SUMIFS('SL T4.26'!H$11:H$2017,'SL T4.26'!$J$11:$J$2017,'BKTT T4.26'!$B22,'SL T4.26'!$K$11:$K$2017,'BKTT T4.26'!$C22) -> 0 | I22: =E22+F22+G22+H22 -> 116 | J22: =K22/I22 -> 576331 | K22: =SUMIFS('SL T4.26'!N$11:N$2017,'SL T4.26'!$J$11:$J$2017,'BKTT T4.26'!$B22,'SL T4.26'!$K$11:$K$2017,'BKTT T4.26'!$C22) -> 66854396 | N22: 576331 | O22: =J22-N22 -> 0 | Q22: hàng 20'
A23: 12 | B23: PAN HA | C23: NHĐV, | D23: Chuyến | E23: =SUMIFS('SL T4.26'!E$11:E$2017,'SL T4.26'!$J$11:$J$2017,'BKTT T4.26'!$B23,'SL T4.26'!$K$11:$K$2017,'BKTT T4.26'!$C23) -> 0 | F23: =SUMIFS('SL T4.26'!F$11:F$2017,'SL T4.26'!$J$11:$J$2017,'BKTT T4.26'!$B23,'SL T4.26'!$K$11:$K$2017,'BKTT T4.26'!$C23) -> 24 | G23: =SUMIFS('SL T4.26'!G$11:G$2017,'SL T4.26'!$J$11:$J$2017,'BKTT T4.26'!$B23,'SL T4.26'!$K$11:$K$2017,'BKTT T4.26'!$C23)+SUMIFS('SL T4.26'!H$11:H$2017,'SL T4.26'!$J$11:$J$2017,'BKTT T4.26'!$B23,'SL T4.26'!$K$11:$K$2017,'BKTT T4.26'!$C23) -> 0 | I23: =E23+F23+G23+H23 -> 24 | J23: =K23/I23 -> 602510 | K23: =SUMIFS('SL T4.26'!N$11:N$2017,'SL T4.26'!$J$11:$J$2017,'BKTT T4.26'!$B23,'SL T4.26'!$K$11:$K$2017,'BKTT T4.26'!$C23) -> 14460240 | N23: 602510 | O23: =J23-N23 -> 0 | Q23: hàng 40'
A24: 13 | B24: PAN HA | C24: NHĐV. | D24: Chuyến | E24: =SUMIFS('SL T4.26'!E$11:E$2017,'SL T4.26'!$J$11:$J$2017,'BKTT T4.26'!$B24,'SL T4.26'!$K$11:$K$2017,'BKTT T4.26'!$C24) -> 0 | F24: =SUMIFS('SL T4.26'!F$11:F$2017,'SL T4.26'!$J$11:$J$2017,'BKTT T4.26'!$B24,'SL T4.26'!$K$11:$K$2017,'BKTT T4.26'!$C24) -> 0 | G24: =SUMIFS('SL T4.26'!G$11:G$2017,'SL T4.26'!$J$11:$J$2017,'BKTT T4.26'!$B24,'SL T4.26'!$K$11:$K$2017,'BKTT T4.26'!$C24)+SUMIFS('SL T4.26'!H$11:H$2017,'SL T4.26'!$J$11:$J$2017,'BKTT T4.26'!$B24,'SL T4.26'!$K$11:$K$2017,'BKTT T4.26'!$C24) -> 0 | I24: =E24+F24+G24+H24 -> 0 | J24: =K24/I24 -> #DIV/0! | K24: =SUMIFS('SL T4.26'!N$11:N$2017,'SL T4.26'!$J$11:$J$2017,'BKTT T4.26'!$B24,'SL T4.26'!$K$11:$K$2017,'BKTT T4.26'!$C24) -> 0 | O24: =J24-N24 -> #DIV/0! | Q24: Vỏ
A25: 14 | B25: NHĐV | C25: PAN HA | D25: Chuyến | E25: =SUMIFS('SL T4.26'!E$11:E$2017,'SL T4.26'!$J$11:$J$2017,'BKTT T4.26'!$B25,'SL T4.26'!$K$11:$K$2017,'BKTT T4.26'!$C25) -> 0 | F25: =SUMIFS('SL T4.26'!F$11:F$2017,'SL T4.26'!$J$11:$J$2017,'BKTT T4.26'!$B25,'SL T4.26'!$K$11:$K$2017,'BKTT T4.26'!$C25) -> 0 | G25: =SUMIFS('SL T4.26'!G$11:G$2017,'SL T4.26'!$J$11:$J$2017,'BKTT T4.26'!$B25,'SL T4.26'!$K$11:$K$2017,'BKTT T4.26'!$C25)+SUMIFS('SL T4.26'!H$11:H$2017,'SL T4.26'!$J$11:$J$2017,'BKTT T4.26'!$B25,'SL T4.26'!$K$11:$K$2017,'BKTT T4.26'!$C25) -> 0 | I25: =E25+F25+G25+H25 -> 0 | J25: =K25/I25 -> #DIV/0! | K25: =SUMIFS('SL T4.26'!N$11:N$2017,'SL T4.26'!$J$11:$J$2017,'BKTT T4.26'!$B25,'SL T4.26'!$K$11:$K$2017,'BKTT T4.26'!$C25) -> 0 | L25: Chuyển bãi | O25: =J25-N25 -> #DIV/0! | Q25: hàng 20'
A26: 15 | B26: NHĐV, | C26: PAN HA | D26: Chuyến | E26: =SUMIFS('SL T4.26'!E$11:E$2017,'SL T4.26'!$J$11:$J$2017,'BKTT T4.26'!$B26,'SL T4.26'!$K$11:$K$2017,'BKTT T4.26'!$C26) -> 0 | F26: =SUMIFS('SL T4.26'!F$11:F$2017,'SL T4.26'!$J$11:$J$2017,'BKTT T4.26'!$B26,'SL T4.26'!$K$11:$K$2017,'BKTT T4.26'!$C26) -> 0 | G26: =SUMIFS('SL T4.26'!G$11:G$2017,'SL T4.26'!$J$11:$J$2017,'BKTT T4.26'!$B26,'SL T4.26'!$K$11:$K$2017,'BKTT T4.26'!$C26)+SUMIFS('SL T4.26'!H$11:H$2017,'SL T4.26'!$J$11:$J$2017,'BKTT T4.26'!$B26,'SL T4.26'!$K$11:$K$2017,'BKTT T4.26'!$C26) -> 0 | I26: =E26+F26+G26+H26 -> 0 | J26: =K26/I26 -> #DIV/0! | K26: =SUMIFS('SL T4.26'!N$11:N$2017,'SL T4.26'!$J$11:$J$2017,'BKTT T4.26'!$B26,'SL T4.26'!$K$11:$K$2017,'BKTT T4.26'!$C26) -> 0 | L26: Chuyển bãi | O26: =J26-N26 -> #DIV/0! | Q26: hàng 40'
A27: 16 | B27: NHĐV. | C27: PAN HA | D27: Chuyến | E27: =SUMIFS('SL T4.26'!E$11:E$2017,'SL T4.26'!$J$11:$J$2017,'BKTT T4.26'!$B27,'SL T4.26'!$K$11:$K$2017,'BKTT T4.26'!$C27) -> 0 | F27: =SUMIFS('SL T4.26'!F$11:F$2017,'SL T4.26'!$J$11:$J$2017,'BKTT T4.26'!$B27,'SL T4.26'!$K$11:$K$2017,'BKTT T4.26'!$C27) -> 0 | G27: =SUMIFS('SL T4.26'!G$11:G$2017,'SL T4.26'!$J$11:$J$2017,'BKTT T4.26'!$B27,'SL T4.26'!$K$11:$K$2017,'BKTT T4.26'!$C27)+SUMIFS('SL T4.26'!H$11:H$2017,'SL T4.26'!$J$11:$J$2017,'BKTT T4.26'!$B27,'SL T4.26'!$K$11:$K$2017,'BKTT T4.26'!$C27) -> 31 | I27: =E27+F27+G27+H27 -> 31 | J27: =K27/I27 -> 585057 | K27: =SUMIFS('SL T4.26'!N$11:N$2017,'SL T4.26'!$J$11:$J$2017,'BKTT T4.26'!$B27,'SL T4.26'!$K$11:$K$2017,'BKTT T4.26'!$C27) -> 18136767 | L27: Chuyển bãi | N27: 585057 | O27: =J27-N27 -> 0 | Q27: Vỏ
A28: 17 | B28: PAN HA | C28: PTSC | D28: Chuyến | E28: =SUMIFS('SL T4.26'!E$11:E$2017,'SL T4.26'!$J$11:$J$2017,'BKTT T4.26'!$B28,'SL T4.26'!$K$11:$K$2017,'BKTT T4.26'!$C28) -> 0 | F28: =SUMIFS('SL T4.26'!F$11:F$2017,'SL T4.26'!$J$11:$J$2017,'BKTT T4.26'!$B28,'SL T4.26'!$K$11:$K$2017,'BKTT T4.26'!$C28) -> 0 | G28: =SUMIFS('SL T4.26'!G$11:G$2017,'SL T4.26'!$J$11:$J$2017,'BKTT T4.26'!$B28,'SL T4.26'!$K$11:$K$2017,'BKTT T4.26'!$C28)+SUMIFS('SL T4.26'!H$11:H$2017,'SL T4.26'!$J$11:$J$2017,'BKTT T4.26'!$B28,'SL T4.26'!$K$11:$K$2017,'BKTT T4.26'!$C28) -> 0 | I28: =E28+F28+G28+H28 -> 0 | J28: =K28/I28 -> #DIV/0! | K28: =SUMIFS('SL T4.26'!N$11:N$2017,'SL T4.26'!$J$11:$J$2017,'BKTT T4.26'!$B28,'SL T4.26'!$K$11:$K$2017,'BKTT T4.26'!$C28) -> 0 | O28: =J28-N28 -> #DIV/0! | Q28: hàng 20'
A29: 18 | B29: PAN HA | C29: PTSC, | D29: Chuyến | E29: =SUMIFS('SL T4.26'!E$11:E$2017,'SL T4.26'!$J$11:$J$2017,'BKTT T4.26'!$B29,'SL T4.26'!$K$11:$K$2017,'BKTT T4.26'!$C29) -> 0 | F29: =SUMIFS('SL T4.26'!F$11:F$2017,'SL T4.26'!$J$11:$J$2017,'BKTT T4.26'!$B29,'SL T4.26'!$K$11:$K$2017,'BKTT T4.26'!$C29) -> 0 | G29: =SUMIFS('SL T4.26'!G$11:G$2017,'SL T4.26'!$J$11:$J$2017,'BKTT T4.26'!$B29,'SL T4.26'!$K$11:$K$2017,'BKTT T4.26'!$C29)+SUMIFS('SL T4.26'!H$11:H$2017,'SL T4.26'!$J$11:$J$2017,'BKTT T4.26'!$B29,'SL T4.26'!$K$11:$K$2017,'BKTT T4.26'!$C29) -> 0 | I29: =E29+F29+G29+H29 -> 0 | J29: =K29/I29 -> #DIV/0! | K29: =SUMIFS('SL T4.26'!N$11:N$2017,'SL T4.26'!$J$11:$J$2017,'BKTT T4.26'!$B29,'SL T4.26'!$K$11:$K$2017,'BKTT T4.26'!$C29) -> 0 | O29: =J29-N29 -> #DIV/0! | Q29: hàng 40'
A30: 19 | B30: PAN HA | C30: PTSC. | D30: Chuyến | E30: =SUMIFS('SL T4.26'!E$11:E$2017,'SL T4.26'!$J$11:$J$2017,'BKTT T4.26'!$B30,'SL T4.26'!$K$11:$K$2017,'BKTT T4.26'!$C30) -> 0 | F30: =SUMIFS('SL T4.26'!F$11:F$2017,'SL T4.26'!$J$11:$J$2017,'BKTT T4.26'!$B30,'SL T4.26'!$K$11:$K$2017,'BKTT T4.26'!$C30) -> 0 | G30: =SUMIFS('SL T4.26'!G$11:G$2017,'SL T4.26'!$J$11:$J$2017,'BKTT T4.26'!$B30,'SL T4.26'!$K$11:$K$2017,'BKTT T4.26'!$C30)+SUMIFS('SL T4.26'!H$11:H$2017,'SL T4.26'!$J$11:$J$2017,'BKTT T4.26'!$B30,'SL T4.26'!$K$11:$K$2017,'BKTT T4.26'!$C30) -> 0 | I30: =E30+F30+G30+H30 -> 0 | J30: =K30/I30 -> #DIV/0! | K30: =SUMIFS('SL T4.26'!N$11:N$2017,'SL T4.26'!$J$11:$J$2017,'BKTT T4.26'!$B30,'SL T4.26'!$K$11:$K$2017,'BKTT T4.26'!$C30) -> 0 | O30: =J30-N30 -> #DIV/0! | Q30: Vỏ
A31: 20 | B31: PAN HA | C31: TÂN VŨ | D31: Chuyến | E31: =SUMIFS('SL T4.26'!E$11:E$2017,'SL T4.26'!$J$11:$J$2017,'BKTT T4.26'!$B31,'SL T4.26'!$K$11:$K$2017,'BKTT T4.26'!$C31) -> 9 | F31: =SUMIFS('SL T4.26'!F$11:F$2017,'SL T4.26'!$J$11:$J$2017,'BKTT T4.26'!$B31,'SL T4.26'!$K$11:$K$2017,'BKTT T4.26'!$C31) -> 0 | G31: =SUMIFS('SL T4.26'!G$11:G$2017,'SL T4.26'!$J$11:$J$2017,'BKTT T4.26'!$B31,'SL T4.26'!$K$11:$K$2017,'BKTT T4.26'!$C31)+SUMIFS('SL T4.26'!H$11:H$2017,'SL T4.26'!$J$11:$J$2017,'BKTT T4.26'!$B31,'SL T4.26'!$K$11:$K$2017,'BKTT T4.26'!$C31) -> 0 | I31: =E31+F31+G31+H31 -> 9 | J31: =K31/I31 -> 593784 | K31: =SUMIFS('SL T4.26'!N$11:N$2017,'SL T4.26'!$J$11:$J$2017,'BKTT T4.26'!$B31,'SL T4.26'!$K$11:$K$2017,'BKTT T4.26'!$C31) -> 5344056 | N31: 593784 | O31: =J31-N31 -> 0 | Q31: hàng 20'
A32: 21 | B32: PAN HA | C32: TÂN VŨ, | D32: Chuyến | E32: =SUMIFS('SL T4.26'!E$11:E$2017,'SL T4.26'!$J$11:$J$2017,'BKTT T4.26'!$B32,'SL T4.26'!$K$11:$K$2017,'BKTT T4.26'!$C32) -> 0 | F32: =SUMIFS('SL T4.26'!F$11:F$2017,'SL T4.26'!$J$11:$J$2017,'BKTT T4.26'!$B32,'SL T4.26'!$K$11:$K$2017,'BKTT T4.26'!$C32) -> 0 | G32: =SUMIFS('SL T4.26'!G$11:G$2017,'SL T4.26'!$J$11:$J$2017,'BKTT T4.26'!$B32,'SL T4.26'!$K$11:$K$2017,'BKTT T4.26'!$C32)+SUMIFS('SL T4.26'!H$11:H$2017,'SL T4.26'!$J$11:$J$2017,'BKTT T4.26'!$B32,'SL T4.26'!$K$11:$K$2017,'BKTT T4.26'!$C32) -> 0 | I32: =E32+F32+G32+H32 -> 0 | J32: =K32/I32 -> #DIV/0! | K32: =SUMIFS('SL T4.26'!N$11:N$2017,'SL T4.26'!$J$11:$J$2017,'BKTT T4.26'!$B32,'SL T4.26'!$K$11:$K$2017,'BKTT T4.26'!$C32) -> 0 | O32: =J32-N32 -> #DIV/0! | Q32: hàng 40'
A33: 22 | B33: PAN HA | C33: TÂN VŨ. | D33: Chuyến | E33: =SUMIFS('SL T4.26'!E$11:E$2017,'SL T4.26'!$J$11:$J$2017,'BKTT T4.26'!$B33,'SL T4.26'!$K$11:$K$2017,'BKTT T4.26'!$C33) -> 0 | F33: =SUMIFS('SL T4.26'!F$11:F$2017,'SL T4.26'!$J$11:$J$2017,'BKTT T4.26'!$B33,'SL T4.26'!$K$11:$K$2017,'BKTT T4.26'!$C33) -> 0 | G33: =SUMIFS('SL T4.26'!G$11:G$2017,'SL T4.26'!$J$11:$J$2017,'BKTT T4.26'!$B33,'SL T4.26'!$K$11:$K$2017,'BKTT T4.26'!$C33)+SUMIFS('SL T4.26'!H$11:H$2017,'SL T4.26'!$J$11:$J$2017,'BKTT T4.26'!$B33,'SL T4.26'!$K$11:$K$2017,'BKTT T4.26'!$C33) -> 2 | I33: =E33+F33+G33+H33 -> 2 | J33: =K33/I33 -> 576331 | K33: =SUMIFS('SL T4.26'!N$11:N$2017,'SL T4.26'!$J$11:$J$2017,'BKTT T4.26'!$B33,'SL T4.26'!$K$11:$K$2017,'BKTT T4.26'!$C33) -> 1152662 | N33: 576331 | O33: =J33-N33 -> 0 | Q33: Vỏ
A34: 23 | B34: PAN HA | C34: ĐÌNH VŨ | D34: Chuyến | E34: =SUMIFS('SL T4.26'!E$11:E$2017,'SL T4.26'!$J$11:$J$2017,'BKTT T4.26'!$B34,'SL T4.26'!$K$11:$K$2017,'BKTT T4.26'!$C34) -> 0 | F34: =SUMIFS('SL T4.26'!F$11:F$2017,'SL T4.26'!$J$11:$J$2017,'BKTT T4.26'!$B34,'SL T4.26'!$K$11:$K$2017,'BKTT T4.26'!$C34) -> 0 | G34: =SUMIFS('SL T4.26'!G$11:G$2017,'SL T4.26'!$J$11:$J$2017,'BKTT T4.26'!$B34,'SL T4.26'!$K$11:$K$2017,'BKTT T4.26'!$C34)+SUMIFS('SL T4.26'!H$11:H$2017,'SL T4.26'!$J$11:$J$2017,'BKTT T4.26'!$B34,'SL T4.26'!$K$11:$K$2017,'BKTT T4.26'!$C34) -> 0 | I34: =E34+F34+G34+H34 -> 0 | J34: =K34/I34 -> #DIV/0! | K34: =SUMIFS('SL T4.26'!N$11:N$2017,'SL T4.26'!$J$11:$J$2017,'BKTT T4.26'!$B34,'SL T4.26'!$K$11:$K$2017,'BKTT T4.26'!$C34) -> 0 | O34: =J34-N34 -> #DIV/0! | Q34: hàng 20'
A35: 24 | B35: PAN HA | C35: ĐÌNH VŨ, | D35: Chuyến | E35: =SUMIFS('SL T4.26'!E$11:E$2017,'SL T4.26'!$J$11:$J$2017,'BKTT T4.26'!$B35,'SL T4.26'!$K$11:$K$2017,'BKTT T4.26'!$C35) -> 0 | F35: =SUMIFS('SL T4.26'!F$11:F$2017,'SL T4.26'!$J$11:$J$2017,'BKTT T4.26'!$B35,'SL T4.26'!$K$11:$K$2017,'BKTT T4.26'!$C35) -> 0 | G35: =SUMIFS('SL T4.26'!G$11:G$2017,'SL T4.26'!$J$11:$J$2017,'BKTT T4.26'!$B35,'SL T4.26'!$K$11:$K$2017,'BKTT T4.26'!$C35)+SUMIFS('SL T4.26'!H$11:H$2017,'SL T4.26'!$J$11:$J$2017,'BKTT T4.26'!$B35,'SL T4.26'!$K$11:$K$2017,'BKTT T4.26'!$C35) -> 0 | I35: =E35+F35+G35+H35 -> 0 | J35: =K35/I35 -> #DIV/0! | K35: =SUMIFS('SL T4.26'!N$11:N$2017,'SL T4.26'!$J$11:$J$2017,'BKTT T4.26'!$B35,'SL T4.26'!$K$11:$K$2017,'BKTT T4.26'!$C35) -> 0 | O35: =J35-N35 -> #DIV/0! | Q35: hàng 40'
A36: 25 | B36: PAN HA | C36: ĐÌNH VŨ. | D36: Chuyến | E36: =SUMIFS('SL T4.26'!E$11:E$2017,'SL T4.26'!$J$11:$J$2017,'BKTT T4.26'!$B36,'SL T4.26'!$K$11:$K$2017,'BKTT T4.26'!$C36) -> 0 | F36: =SUMIFS('SL T4.26'!F$11:F$2017,'SL T4.26'!$J$11:$J$2017,'BKTT T4.26'!$B36,'SL T4.26'!$K$11:$K$2017,'BKTT T4.26'!$C36) -> 0 | G36: =SUMIFS('SL T4.26'!G$11:G$2017,'SL T4.26'!$J$11:$J$2017,'BKTT T4.26'!$B36,'SL T4.26'!$K$11:$K$2017,'BKTT T4.26'!$C36)+SUMIFS('SL T4.26'!H$11:H$2017,'SL T4.26'!$J$11:$J$2017,'BKTT T4.26'!$B36,'SL T4.26'!$K$11:$K$2017,'BKTT T4.26'!$C36) -> 0 | I36: =E36+F36+G36+H36 -> 0 | J36: =K36/I36 -> #DIV/0! | K36: =SUMIFS('SL T4.26'!N$11:N$2017,'SL T4.26'!$J$11:$J$2017,'BKTT T4.26'!$B36,'SL T4.26'!$K$11:$K$2017,'BKTT T4.26'!$C36) -> 0 | O36: =J36-N36 -> #DIV/0! | Q36: Vỏ
A37: 26 | B37: PAN HA | C37: VIMC | D37: Chuyến | E37: =SUMIFS('SL T4.26'!E$11:E$2017,'SL T4.26'!$J$11:$J$2017,'BKTT T4.26'!$B37,'SL T4.26'!$K$11:$K$2017,'BKTT T4.26'!$C37) -> 0 | F37: =SUMIFS('SL T4.26'!F$11:F$2017,'SL T4.26'!$J$11:$J$2017,'BKTT T4.26'!$B37,'SL T4.26'!$K$11:$K$2017,'BKTT T4.26'!$C37) -> 0 | G37: =SUMIFS('SL T4.26'!G$11:G$2017,'SL T4.26'!$J$11:$J$2017,'BKTT T4.26'!$B37,'SL T4.26'!$K$11:$K$2017,'BKTT T4.26'!$C37)+SUMIFS('SL T4.26'!H$11:H$2017,'SL T4.26'!$J$11:$J$2017,'BKTT T4.26'!$B37,'SL T4.26'!$K$11:$K$2017,'BKTT T4.26'!$C37) -> 0 | I37: =E37+F37+G37+H37 -> 0 | J37: =K37/I37 -> #DIV/0! | K37: =SUMIFS('SL T4.26'!N$11:N$2017,'SL T4.26'!$J$11:$J$2017,'BKTT T4.26'!$B37,'SL T4.26'!$K$11:$K$2017,'BKTT T4.26'!$C37) -> 0 | O37: =J37-N37 -> #DIV/0! | Q37: hàng 20'
A38: 27 | B38: PAN HA | C38: VIP | D38: Chuyến | E38: =SUMIFS('SL T4.26'!E$11:E$2017,'SL T4.26'!$J$11:$J$2017,'BKTT T4.26'!$B38,'SL T4.26'!$K$11:$K$2017,'BKTT T4.26'!$C38) -> 51 | F38: =SUMIFS('SL T4.26'!F$11:F$2017,'SL T4.26'!$J$11:$J$2017,'BKTT T4.26'!$B38,'SL T4.26'!$K$11:$K$2017,'BKTT T4.26'!$C38) -> 0 | G38: =SUMIFS('SL T4.26'!G$11:G$2017,'SL T4.26'!$J$11:$J$2017,'BKTT T4.26'!$B38,'SL T4.26'!$K$11:$K$2017,'BKTT T4.26'!$C38)+SUMIFS('SL T4.26'!H$11:H$2017,'SL T4.26'!$J$11:$J$2017,'BKTT T4.26'!$B38,'SL T4.26'!$K$11:$K$2017,'BKTT T4.26'!$C38) -> 0 | I38: =E38+F38+G38+H38 -> 51 | J38: =K38/I38 -> 576331 | K38: =SUMIFS('SL T4.26'!N$11:N$2017,'SL T4.26'!$J$11:$J$2017,'BKTT T4.26'!$B38,'SL T4.26'!$K$11:$K$2017,'BKTT T4.26'!$C38) -> 29392881 | N38: 576331 | O38: =J38-N38 -> 0 | Q38: hàng 20'
A39: 28 | B39: PAN HA | C39: VIP, | D39: Chuyến | E39: =SUMIFS('SL T4.26'!E$11:E$2017,'SL T4.26'!$J$11:$J$2017,'BKTT T4.26'!$B39,'SL T4.26'!$K$11:$K$2017,'BKTT T4.26'!$C39) -> 0 | F39: =SUMIFS('SL T4.26'!F$11:F$2017,'SL T4.26'!$J$11:$J$2017,'BKTT T4.26'!$B39,'SL T4.26'!$K$11:$K$2017,'BKTT T4.26'!$C39) -> 20 | G39: =SUMIFS('SL T4.26'!G$11:G$2017,'SL T4.26'!$J$11:$J$2017,'BKTT T4.26'!$B39,'SL T4.26'!$K$11:$K$2017,'BKTT T4.26'!$C39)+SUMIFS('SL T4.26'!H$11:H$2017,'SL T4.26'!$J$11:$J$2017,'BKTT T4.26'!$B39,'SL T4.26'!$K$11:$K$2017,'BKTT T4.26'!$C39) -> 0 | I39: =E39+F39+G39+H39 -> 20 | J39: =K39/I39 -> 602510 | K39: =SUMIFS('SL T4.26'!N$11:N$2017,'SL T4.26'!$J$11:$J$2017,'BKTT T4.26'!$B39,'SL T4.26'!$K$11:$K$2017,'BKTT T4.26'!$C39) -> 12050200 | N39: 602510 | O39: =J39-N39 -> 0 | Q39: hàng 40'
A40: 29 | B40: PAN HA | C40: VIP. | D40: Chuyến | E40: =SUMIFS('SL T4.26'!E$11:E$2017,'SL T4.26'!$J$11:$J$2017,'BKTT T4.26'!$B40,'SL T4.26'!$K$11:$K$2017,'BKTT T4.26'!$C40) -> 0 | F40: =SUMIFS('SL T4.26'!F$11:F$2017,'SL T4.26'!$J$11:$J$2017,'BKTT T4.26'!$B40,'SL T4.26'!$K$11:$K$2017,'BKTT T4.26'!$C40) -> 0 | G40: =SUMIFS('SL T4.26'!G$11:G$2017,'SL T4.26'!$J$11:$J$2017,'BKTT T4.26'!$B40,'SL T4.26'!$K$11:$K$2017,'BKTT T4.26'!$C40)+SUMIFS('SL T4.26'!H$11:H$2017,'SL T4.26'!$J$11:$J$2017,'BKTT T4.26'!$B40,'SL T4.26'!$K$11:$K$2017,'BKTT T4.26'!$C40) -> 15 | I40: =E40+F40+G40+H40 -> 15 | J40: =K40/I40 -> 550151 | K40: =SUMIFS('SL T4.26'!N$11:N$2017,'SL T4.26'!$J$11:$J$2017,'BKTT T4.26'!$B40,'SL T4.26'!$K$11:$K$2017,'BKTT T4.26'!$C40) -> 8252265 | N40: 550151 | O40: =J40-N40 -> 0 | Q40: Vỏ
A41: 30 | B41: PAN HA | C41: ICD NH | D41: Chuyến | E41: =SUMIFS('SL T4.26'!E$11:E$2017,'SL T4.26'!$J$11:$J$2017,'BKTT T4.26'!$B41,'SL T4.26'!$K$11:$K$2017,'BKTT T4.26'!$C41) -> 0 | F41: =SUMIFS('SL T4.26'!F$11:F$2017,'SL T4.26'!$J$11:$J$2017,'BKTT T4.26'!$B41,'SL T4.26'!$K$11:$K$2017,'BKTT T4.26'!$C41) -> 0 | G41: =SUMIFS('SL T4.26'!G$11:G$2017,'SL T4.26'!$J$11:$J$2017,'BKTT T4.26'!$B41,'SL T4.26'!$K$11:$K$2017,'BKTT T4.26'!$C41)+SUMIFS('SL T4.26'!H$11:H$2017,'SL T4.26'!$J$11:$J$2017,'BKTT T4.26'!$B41,'SL T4.26'!$K$11:$K$2017,'BKTT T4.26'!$C41) -> 0 | I41: =E41+F41+G41+H41 -> 0 | J41: =K41/I41 -> #DIV/0! | K41: =SUMIFS('SL T4.26'!N$11:N$2017,'SL T4.26'!$J$11:$J$2017,'BKTT T4.26'!$B41,'SL T4.26'!$K$11:$K$2017,'BKTT T4.26'!$C41) -> 0 | O41: =J41-N41 -> #DIV/0! | Q41: hàng 20'
A42: 31 | B42: PAN HA | C42: ICD NH, | D42: Chuyến | E42: =SUMIFS('SL T4.26'!E$11:E$2017,'SL T4.26'!$J$11:$J$2017,'BKTT T4.26'!$B42,'SL T4.26'!$K$11:$K$2017,'BKTT T4.26'!$C42) -> 0 | F42: =SUMIFS('SL T4.26'!F$11:F$2017,'SL T4.26'!$J$11:$J$2017,'BKTT T4.26'!$B42,'SL T4.26'!$K$11:$K$2017,'BKTT T4.26'!$C42) -> 0 | G42: =SUMIFS('SL T4.26'!G$11:G$2017,'SL T4.26'!$J$11:$J$2017,'BKTT T4.26'!$B42,'SL T4.26'!$K$11:$K$2017,'BKTT T4.26'!$C42)+SUMIFS('SL T4.26'!H$11:H$2017,'SL T4.26'!$J$11:$J$2017,'BKTT T4.26'!$B42,'SL T4.26'!$K$11:$K$2017,'BKTT T4.26'!$C42) -> 0 | I42: =E42+F42+G42+H42 -> 0 | J42: =K42/I42 -> #DIV/0! | K42: =SUMIFS('SL T4.26'!N$11:N$2017,'SL T4.26'!$J$11:$J$2017,'BKTT T4.26'!$B42,'SL T4.26'!$K$11:$K$2017,'BKTT T4.26'!$C42) -> 0 | O42: =J42-N42 -> #DIV/0! | Q42: hàng 40'
...

Sheet SL T4.26
A1: CÔNG TY TNHH AMT PHÚC LỘC
A2: Số nhà 56B/97 đường Đoàn Kết,Phường Hải An, TP Hải Phòng
A3: MST: 0201965047
A5: BẢNG KÊ QUYẾT TOÁN CƯỚC VẬN CHUYỂN THÁNG 04/2026
A6: Từ ngày 26/03/2026 đến ngày 25/04/2026
A7: KHÁCH HÀNG: | C7: CÔNG TY TNHH PAN HẢI AN
A8: Công ty TNHH AMT Phúc Lộc xin gửi tới Quý Công ty bảng kê quyết toán vận tải như sau: | R8: . BKS:
R9: tuyến đường
A10: STT | B10: NGÀY ĐI | C10: CHỦ HÀNG | D10: SỐCONTAINER | E10: F20' | F10: F40' | G10: E20' | H10: E40' | I10: SỐ XE CHẠY | J10: ĐIỂM ĐI | K10: ĐIỂM ĐẾN | L10: SỐ CHUYẾN | M10: CƯỚC CHUYẾN | N10: TỔNG TT | O10: TÁC NGHIỆP | P10: GHI CHÚ | R10: Cước vận chuyển Container | S10: -
E11: =SUBTOTAL(9,E12:E2022) -> 594 | F11: =SUBTOTAL(9,F12:F2022) -> 286 | G11: =SUBTOTAL(9,G12:G2022) -> 38 | H11: =SUBTOTAL(9,H12:H2022) -> 251 | L11: =SUBTOTAL(9,L12:L2022) -> 1169 | N11: =SUBTOTAL(9,N12:N1218) -> 764422896 | R11: Nội dung HĐ | S11: Hàng 20' | T11: Hàng 40' | U11: Vỏ | V11: Ký hiệu cước
A12: 1 | B12: 46107 | C12: PAN | D12: OBLU3323816 | E12: 1 | I12: 15C17442 | J12: PAN HA | K12: NDV | L12: =E12+F12+G12+H12 -> 1 | M12: {=INDEX('BKTT T4.26'!$N$12:$N$55,MATCH(V12,'BKTT T4.26'!$A$12:$A$55,0),0)} -> 454158 | N12: =L12*M12 -> 454158 | O12: XUAT TAU | P12: oke | R12: =$R$10&S12&$R$9&J12&$S$10&K12&$R$8&I12 -> Cước vận chuyển Container hàng 20' tuyến đường PAN HA - NDV. BKS: 15C17442 | S12: =IF(E12=1," hàng 20' ",IF(F12=1," hàng 40' "," vỏ ")) -> hàng 20' | V12: 7
A13: 2 | B13: 46107 | C13: PAN | D13: OBLU8819244 | F13: 1 | I13: 15C17442 | J13: PAN HA | K13: NDV, | L13: =E13+F13+G13+H13 -> 1 | M13: {=INDEX('BKTT T4.26'!$N$12:$N$55,MATCH(V13,'BKTT T4.26'!$A$12:$A$55,0),0)} -> 489065 | N13: =L13*M13 -> 489065 | O13: XUAT TAU | P13: oke | R13: =$R$10&S13&$R$9&J13&$S$10&K13&$R$8&I13 -> Cước vận chuyển Container hàng 40' tuyến đường PAN HA - NDV,. BKS: 15C17442 | S13: =IF(E13=1," hàng 20' ",IF(F13=1," hàng 40' "," vỏ ")) -> hàng 40' | V13: 8
A14: 3 | B14: 46107 | C14: PAN | D14: HAMU1331878 | H14: 1 | I14: 15C17442 | J14: HATECO | K14: PAN HA | L14: =E14+F14+G14+H14 -> 1 | M14: {=INDEX('BKTT T4.26'!$N$12:$N$55,MATCH(V14,'BKTT T4.26'!$A$12:$A$55,0),0)} -> 1002400 | N14: =L14*M14 -> 1002400 | O14: CHUYEN BAI | P14: oke | R14: =$R$10&S14&$R$9&J14&$S$10&K14&$R$8&I14 -> Cước vận chuyển Container vỏ tuyến đường HATECO - PAN HA. BKS: 15C17442 | S14: =IF(E14=1," hàng 20' ",IF(F14=1," hàng 40' "," vỏ ")) -> vỏ | V14: 35
A15: 4 | B15: 46107 | C15: PAN | D15: MRSU5143968 | H15: 1 | I15: 15H07644 | J15: HATECO | K15: PAN HA | L15: =E15+F15+G15+H15 -> 1 | M15: {=INDEX('BKTT T4.26'!$N$12:$N$55,MATCH(V15,'BKTT T4.26'!$A$12:$A$55,0),0)} -> 1002400 | N15: =L15*M15 -> 1002400 | O15: CHUYEN BAI | P15: oke | R15: =$R$10&S15&$R$9&J15&$S$10&K15&$R$8&I15 -> Cước vận chuyển Container vỏ tuyến đường HATECO - PAN HA. BKS: 15H07644 | S15: =IF(E15=1," hàng 20' ",IF(F15=1," hàng 40' "," vỏ ")) -> vỏ | V15: 35
A16: 5 | B16: 46107 | C16: PAN | D16: HASU4838528 | H16: 1 | I16: 15H07644 | J16: HATECO | K16: PAN HA | L16: =E16+F16+G16+H16 -> 1 | M16: {=INDEX('BKTT T4.26'!$N$12:$N$55,MATCH(V16,'BKTT T4.26'!$A$12:$A$55,0),0)} -> 1002400 | N16: =L16*M16 -> 1002400 | O16: CHUYEN BAI | P16: oke | R16: =$R$10&S16&$R$9&J16&$S$10&K16&$R$8&I16 -> Cước vận chuyển Container vỏ tuyến đường HATECO - PAN HA. BKS: 15H07644 | S16: =IF(E16=1," hàng 20' ",IF(F16=1," hàng 40' "," vỏ ")) -> vỏ | V16: 35
A17: 6 | B17: 46107 | C17: PAN | D17: MRKU2870533 | H17: 1 | I17: 15H07788 | J17: HATECO | K17: PAN HA | L17: =E17+F17+G17+H17 -> 1 | M17: {=INDEX('BKTT T4.26'!$N$12:$N$55,MATCH(V17,'BKTT T4.26'!$A$12:$A$55,0),0)} -> 1002400 | N17: =L17*M17 -> 1002400 | O17: CHUYEN BAI | P17: oke | R17: =$R$10&S17&$R$9&J17&$S$10&K17&$R$8&I17 -> Cước vận chuyển Container vỏ tuyến đường HATECO - PAN HA. BKS: 15H07788 | S17: =IF(E17=1," hàng 20' ",IF(F17=1," hàng 40' "," vỏ ")) -> vỏ | V17: 35
A18: 7 | B18: 46108 | C18: PAN | D18: SEKU1786449 | E18: 1 | I18: 15H12925 | J18: PAN HA | K18: HẢI AN | L18: =E18+F18+G18+H18 -> 1 | M18: {=INDEX('BKTT T4.26'!$N$12:$N$55,MATCH(V18,'BKTT T4.26'!$A$12:$A$55,0),0)} -> 654871 | N18: =L18*M18 -> 654871 | O18: XUAT TAU | P18: oke | R18: =$R$10&S18&$R$9&J18&$S$10&K18&$R$8&I18 -> Cước vận chuyển Container hàng 20' tuyến đường PAN HA - HẢI AN. BKS: 15H12925 | S18: =IF(E18=1," hàng 20' ",IF(F18=1," hàng 40' "," vỏ ")) -> hàng 20' | V18: 1
A19: 8 | B19: 46108 | C19: PAN | D19: HACU4222377 | F19: 1 | I19: 15H12925 | J19: PAN HA | K19: HẢI AN, | L19: =E19+F19+G19+H19 -> 1 | M19: {=INDEX('BKTT T4.26'!$N$12:$N$55,MATCH(V19,'BKTT T4.26'!$A$12:$A$55,0),0)} -> 681050 | N19: =L19*M19 -> 681050 | O19: XUAT TAU | P19: oke | R19: =$R$10&S19&$R$9&J19&$S$10&K19&$R$8&I19 -> Cước vận chuyển Container hàng 40' tuyến đường PAN HA - HẢI AN,. BKS: 15H12925 | S19: =IF(E19=1," hàng 20' ",IF(F19=1," hàng 40' "," vỏ ")) -> hàng 40' | V19: 2
A20: 9 | B20: 46108 | C20: PAN | D20: HACU4180414 | F20: 1 | I20: 15H12925 | J20: PAN HA | K20: HẢI AN, | L20: =E20+F20+G20+H20 -> 1 | M20: {=INDEX('BKTT T4.26'!$N$12:$N$55,MATCH(V20,'BKTT T4.26'!$A$12:$A$55,0),0)} -> 681050 | N20: =L20*M20 -> 681050 | O20: XUAT TAU | P20: oke | R20: =$R$10&S20&$R$9&J20&$S$10&K20&$R$8&I20 -> Cước vận chuyển Container hàng 40' tuyến đường PAN HA - HẢI AN,. BKS: 15H12925 | S20: =IF(E20=1," hàng 20' ",IF(F20=1," hàng 40' "," vỏ ")) -> hàng 40' | V20: 2
A21: 10 | B21: 46108 | C21: PAN | D21: SELU4506256 | F21: 1 | I21: 15H12925 | J21: PAN HA | K21: HẢI AN, | L21: =E21+F21+G21+H21 -> 1 | M21: {=INDEX('BKTT T4.26'!$N$12:$N$55,MATCH(V21,'BKTT T4.26'!$A$12:$A$55,0),0)} -> 681050 | N21: =L21*M21 -> 681050 | O21: XUAT TAU | P21: oke | R21: =$R$10&S21&$R$9&J21&$S$10&K21&$R$8&I21 -> Cước vận chuyển Container hàng 40' tuyến đường PAN HA - HẢI AN,. BKS: 15H12925 | S21: =IF(E21=1," hàng 20' ",IF(F21=1," hàng 40' "," vỏ ")) -> hàng 40' | V21: 2
A22: 11 | B22: 46108 | C22: PAN | D22: DFSU2824836 | E22: 1 | I22: 15H07524 | J22: PAN HA | K22: HẢI AN | L22: =E22+F22+G22+H22 -> 1 | M22: {=INDEX('BKTT T4.26'!$N$12:$N$55,MATCH(V22,'BKTT T4.26'!$A$12:$A$55,0),0)} -> 654871 | N22: =L22*M22 -> 654871 | O22: XUAT TAU | P22: oke | R22: =$R$10&S22&$R$9&J22&$S$10&K22&$R$8&I22 -> Cước vận chuyển Container hàng 20' tuyến đường PAN HA - HẢI AN. BKS: 15H07524 | S22: =IF(E22=1," hàng 20' ",IF(F22=1," hàng 40' "," vỏ ")) -> hàng 20' | V22: 1
A23: 12 | B23: 46108 | C23: PAN | D23: HAHU8303670 | E23: 1 | I23: 15H07524 | J23: PAN HA | K23: HẢI AN | L23: =E23+F23+G23+H23 -> 1 | M23: {=INDEX('BKTT T4.26'!$N$12:$N$55,MATCH(V23,'BKTT T4.26'!$A$12:$A$55,0),0)} -> 654871 | N23: =L23*M23 -> 654871 | O23: XUAT TAU | P23: oke | R23: =$R$10&S23&$R$9&J23&$S$10&K23&$R$8&I23 -> Cước vận chuyển Container hàng 20' tuyến đường PAN HA - HẢI AN. BKS: 15H07524 | S23: =IF(E23=1," hàng 20' ",IF(F23=1," hàng 40' "," vỏ ")) -> hàng 20' | V23: 1
A24: 13 | B24: 46108 | C24: PAN | D24: DFSU1745970 | E24: 1 | I24: 15C17301 | J24: PAN HA | K24: HẢI AN | L24: =E24+F24+G24+H24 -> 1 | M24: {=INDEX('BKTT T4.26'!$N$12:$N$55,MATCH(V24,'BKTT T4.26'!$A$12:$A$55,0),0)} -> 654871 | N24: =L24*M24 -> 654871 | O24: XUAT TAU | P24: oke | R24: =$R$10&S24&$R$9&J24&$S$10&K24&$R$8&I24 -> Cước vận chuyển Container hàng 20' tuyến đường PAN HA - HẢI AN. BKS: 15C17301 | S24: =IF(E24=1," hàng 20' ",IF(F24=1," hàng 40' "," vỏ ")) -> hàng 20' | V24: 1
A25: 14 | B25: 46108 | C25: PAN | D25: HACU2244675 | E25: 1 | I25: 15C17301 | J25: PAN HA | K25: HẢI AN | L25: =E25+F25+G25+H25 -> 1 | M25: {=INDEX('BKTT T4.26'!$N$12:$N$55,MATCH(V25,'BKTT T4.26'!$A$12:$A$55,0),0)} -> 654871 | N25: =L25*M25 -> 654871 | O25: XUAT TAU | P25: oke | R25: =$R$10&S25&$R$9&J25&$S$10&K25&$R$8&I25 -> Cước vận chuyển Container hàng 20' tuyến đường PAN HA - HẢI AN. BKS: 15C17301 | S25: =IF(E25=1," hàng 20' ",IF(F25=1," hàng 40' "," vỏ ")) -> hàng 20' | V25: 1
A26: 15 | B26: 46108 | C26: PAN | D26: SEKU1809987 | E26: 1 | I26: 15C17301 | J26: PAN HA | K26: HẢI AN | L26: =E26+F26+G26+H26 -> 1 | M26: {=INDEX('BKTT T4.26'!$N$12:$N$55,MATCH(V26,'BKTT T4.26'!$A$12:$A$55,0),0)} -> 654871 | N26: =L26*M26 -> 654871 | O26: XUAT TAU | P26: oke | R26: =$R$10&S26&$R$9&J26&$S$10&K26&$R$8&I26 -> Cước vận chuyển Container hàng 20' tuyến đường PAN HA - HẢI AN. BKS: 15C17301 | S26: =IF(E26=1," hàng 20' ",IF(F26=1," hàng 40' "," vỏ ")) -> hàng 20' | V26: 1
A27: 16 | B27: 46108 | C27: PAN | D27: SEKU1942650 | E27: 1 | I27: 15C17301 | J27: PAN HA | K27: HẢI AN | L27: =E27+F27+G27+H27 -> 1 | M27: {=INDEX('BKTT T4.26'!$N$12:$N$55,MATCH(V27,'BKTT T4.26'!$A$12:$A$55,0),0)} -> 654871 | N27: =L27*M27 -> 654871 | O27: XUAT TAU | P27: oke | R27: =$R$10&S27&$R$9&J27&$S$10&K27&$R$8&I27 -> Cước vận chuyển Container hàng 20' tuyến đường PAN HA - HẢI AN. BKS: 15C17301 | S27: =IF(E27=1," hàng 20' ",IF(F27=1," hàng 40' "," vỏ ")) -> hàng 20' | V27: 1
A28: 17 | B28: 46108 | C28: PAN | D28: HACU2243920 | E28: 1 | I28: 15C17301 | J28: PAN HA | K28: HẢI AN | L28: =E28+F28+G28+H28 -> 1 | M28: {=INDEX('BKTT T4.26'!$N$12:$N$55,MATCH(V28,'BKTT T4.26'!$A$12:$A$55,0),0)} -> 654871 | N28: =L28*M28 -> 654871 | O28: XUAT TAU | P28: oke | R28: =$R$10&S28&$R$9&J28&$S$10&K28&$R$8&I28 -> Cước vận chuyển Container hàng 20' tuyến đường PAN HA - HẢI AN. BKS: 15C17301 | S28: =IF(E28=1," hàng 20' ",IF(F28=1," hàng 40' "," vỏ ")) -> hàng 20' | V28: 1
A29: 18 | B29: 46108 | C29: PAN | D29: TGCU0175311 | E29: 1 | I29: 15C17301 | J29: PAN HA | K29: HẢI AN | L29: =E29+F29+G29+H29 -> 1 | M29: {=INDEX('BKTT T4.26'!$N$12:$N$55,MATCH(V29,'BKTT T4.26'!$A$12:$A$55,0),0)} -> 654871 | N29: =L29*M29 -> 654871 | O29: XUAT TAU | P29: oke | R29: =$R$10&S29&$R$9&J29&$S$10&K29&$R$8&I29 -> Cước vận chuyển Container hàng 20' tuyến đường PAN HA - HẢI AN. BKS: 15C17301 | S29: =IF(E29=1," hàng 20' ",IF(F29=1," hàng 40' "," vỏ ")) -> hàng 20' | V29: 1
A30: 19 | B30: 46108 | C30: PAN | D30: HACU4220013 | F30: 1 | I30: 15C17301 | J30: PAN HA | K30: HẢI AN, | L30: =E30+F30+G30+H30 -> 1 | M30: {=INDEX('BKTT T4.26'!$N$12:$N$55,MATCH(V30,'BKTT T4.26'!$A$12:$A$55,0),0)} -> 681050 | N30: =L30*M30 -> 681050 | O30: XUAT TAU | P30: oke | R30: =$R$10&S30&$R$9&J30&$S$10&K30&$R$8&I30 -> Cước vận chuyển Container hàng 40' tuyến đường PAN HA - HẢI AN,. BKS: 15C17301 | S30: =IF(E30=1," hàng 20' ",IF(F30=1," hàng 40' "," vỏ ")) -> hàng 40' | V30: 2
A31: 20 | B31: 46108 | C31: PAN | D31: SEKU5576728 | F31: 1 | I31: 15C17301 | J31: PAN HA | K31: HẢI AN, | L31: =E31+F31+G31+H31 -> 1 | M31: {=INDEX('BKTT T4.26'!$N$12:$N$55,MATCH(V31,'BKTT T4.26'!$A$12:$A$55,0),0)} -> 681050 | N31: =L31*M31 -> 681050 | O31: XUAT TAU | P31: oke | R31: =$R$10&S31&$R$9&J31&$S$10&K31&$R$8&I31 -> Cước vận chuyển Container hàng 40' tuyến đường PAN HA - HẢI AN,. BKS: 15C17301 | S31: =IF(E31=1," hàng 20' ",IF(F31=1," hàng 40' "," vỏ ")) -> hàng 40' | V31: 2
A32: 21 | B32: 46108 | C32: PAN | D32: CAAU6411939 | F32: 1 | I32: 15C17301 | J32: PAN HA | K32: HẢI AN, | L32: =E32+F32+G32+H32 -> 1 | M32: {=INDEX('BKTT T4.26'!$N$12:$N$55,MATCH(V32,'BKTT T4.26'!$A$12:$A$55,0),0)} -> 681050 | N32: =L32*M32 -> 681050 | O32: XUAT TAU | P32: oke | R32: =$R$10&S32&$R$9&J32&$S$10&K32&$R$8&I32 -> Cước vận chuyển Container hàng 40' tuyến đường PAN HA - HẢI AN,. BKS: 15C17301 | S32: =IF(E32=1," hàng 20' ",IF(F32=1," hàng 40' "," vỏ ")) -> hàng 40' | V32: 2
A33: 22 | B33: 46108 | C33: PAN | D33: GAOU7899199 | F33: 1 | I33: 15C17301 | J33: PAN HA | K33: HẢI AN, | L33: =E33+F33+G33+H33 -> 1 | M33: {=INDEX('BKTT T4.26'!$N$12:$N$55,MATCH(V33,'BKTT T4.26'!$A$12:$A$55,0),0)} -> 681050 | N33: =L33*M33 -> 681050 | O33: XUAT TAU | P33: oke | R33: =$R$10&S33&$R$9&J33&$S$10&K33&$R$8&I33 -> Cước vận chuyển Container hàng 40' tuyến đường PAN HA - HẢI AN,. BKS: 15C17301 | S33: =IF(E33=1," hàng 20' ",IF(F33=1," hàng 40' "," vỏ ")) -> hàng 40' | V33: 2
A34: 23 | B34: 46108 | C34: PAN | D34: FCIU5643714 | E34: 1 | I34: 15C17442 | J34: PAN HA | K34: HẢI AN | L34: =E34+F34+G34+H34 -> 1 | M34: {=INDEX('BKTT T4.26'!$N$12:$N$55,MATCH(V34,'BKTT T4.26'!$A$12:$A$55,0),0)} -> 654871 | N34: =L34*M34 -> 654871 | O34: XUAT TAU | P34: oke | R34: =$R$10&S34&$R$9&J34&$S$10&K34&$R$8&I34 -> Cước vận chuyển Container hàng 20' tuyến đường PAN HA - HẢI AN. BKS: 15C17442 | S34: =IF(E34=1," hàng 20' ",IF(F34=1," hàng 40' "," vỏ ")) -> hàng 20' | V34: 1
A35: 24 | B35: 46108 | C35: PAN | D35: HACU2242245 | E35: 1 | I35: 15C17442 | J35: PAN HA | K35: HẢI AN | L35: =E35+F35+G35+H35 -> 1 | M35: {=INDEX('BKTT T4.26'!$N$12:$N$55,MATCH(V35,'BKTT T4.26'!$A$12:$A$55,0),0)} -> 654871 | N35: =L35*M35 -> 654871 | O35: XUAT TAU | P35: oke | R35: =$R$10&S35&$R$9&J35&$S$10&K35&$R$8&I35 -> Cước vận chuyển Container hàng 20' tuyến đường PAN HA - HẢI AN. BKS: 15C17442 | S35: =IF(E35=1," hàng 20' ",IF(F35=1," hàng 40' "," vỏ ")) -> hàng 20' | V35: 1
A36: 25 | B36: 46108 | C36: PAN | D36: HACU2214670 | E36: 1 | I36: 15C17442 | J36: PAN HA | K36: HẢI AN | L36: =E36+F36+G36+H36 -> 1 | M36: {=INDEX('BKTT T4.26'!$N$12:$N$55,MATCH(V36,'BKTT T4.26'!$A$12:$A$55,0),0)} -> 654871 | N36: =L36*M36 -> 654871 | O36: XUAT TAU | P36: oke | R36: =$R$10&S36&$R$9&J36&$S$10&K36&$R$8&I36 -> Cước vận chuyển Container hàng 20' tuyến đường PAN HA - HẢI AN. BKS: 15C17442 | S36: =IF(E36=1," hàng 20' ",IF(F36=1," hàng 40' "," vỏ ")) -> hàng 20' | V36: 1
A37: 26 | B37: 46108 | C37: PAN | D37: DFSU3148232 | E37: 1 | I37: 15C17442 | J37: PAN HA | K37: HẢI AN | L37: =E37+F37+G37+H37 -> 1 | M37: {=INDEX('BKTT T4.26'!$N$12:$N$55,MATCH(V37,'BKTT T4.26'!$A$12:$A$55,0),0)} -> 654871 | N37: =L37*M37 -> 654871 | O37: XUAT TAU | P37: oke | R37: =$R$10&S37&$R$9&J37&$S$10&K37&$R$8&I37 -> Cước vận chuyển Container hàng 20' tuyến đường PAN HA - HẢI AN. BKS: 15C17442 | S37: =IF(E37=1," hàng 20' ",IF(F37=1," hàng 40' "," vỏ ")) -> hàng 20' | V37: 1
A38: 27 | B38: 46108 | C38: PAN | D38: TGCU2027329 | E38: 1 | I38: 15C17442 | J38: PAN HA | K38: HẢI AN | L38: =E38+F38+G38+H38 -> 1 | M38: {=INDEX('BKTT T4.26'!$N$12:$N$55,MATCH(V38,'BKTT T4.26'!$A$12:$A$55,0),0)} -> 654871 | N38: =L38*M38 -> 654871 | O38: XUAT TAU | P38: oke | R38: =$R$10&S38&$R$9&J38&$S$10&K38&$R$8&I38 -> Cước vận chuyển Container hàng 20' tuyến đường PAN HA - HẢI AN. BKS: 15C17442 | S38: =IF(E38=1," hàng 20' ",IF(F38=1," hàng 40' "," vỏ ")) -> hàng 20' | V38: 1
A39: 28 | B39: 46108 | C39: PAN | D39: TGCU0115708 | E39: 1 | I39: 15C17442 | J39: PAN HA | K39: HẢI AN | L39: =E39+F39+G39+H39 -> 1 | M39: {=INDEX('BKTT T4.26'!$N$12:$N$55,MATCH(V39,'BKTT T4.26'!$A$12:$A$55,0),0)} -> 654871 | N39: =L39*M39 -> 654871 | O39: XUAT TAU | P39: oke | R39: =$R$10&S39&$R$9&J39&$S$10&K39&$R$8&I39 -> Cước vận chuyển Container hàng 20' tuyến đường PAN HA - HẢI AN. BKS: 15C17442 | S39: =IF(E39=1," hàng 20' ",IF(F39=1," hàng 40' "," vỏ ")) -> hàng 20' | V39: 1
A40: 29 | B40: 46108 | C40: PAN | D40: HACU4211011 | F40: 1 | I40: 15C17442 | J40: PAN HA | K40: HẢI AN, | L40: =E40+F40+G40+H40 -> 1 | M40: {=INDEX('BKTT T4.26'!$N$12:$N$55,MATCH(V40,'BKTT T4.26'!$A$12:$A$55,0),0)} -> 681050 | N40: =L40*M40 -> 681050 | O40: XUAT TAU | P40: oke | R40: =$R$10&S40&$R$9&J40&$S$10&K40&$R$8&I40 -> Cước vận chuyển Container hàng 40' tuyến đường PAN HA - HẢI AN,. BKS: 15C17442 | S40: =IF(E40=1," hàng 20' ",IF(F40=1," hàng 40' "," vỏ ")) -> hàng 40' | V40: 2
A41: 30 | B41: 46108 | C41: PAN | D41: TCNU6733187 | F41: 1 | I41: 15C17442 | J41: PAN HA | K41: HẢI AN, | L41: =E41+F41+G41+H41 -> 1 | M41: {=INDEX('BKTT T4.26'!$N$12:$N$55,MATCH(V41,'BKTT T4.26'!$A$12:$A$55,0),0)} -> 681050 | N41: =L41*M41 -> 681050 | O41: XUAT TAU | P41: oke | R41: =$R$10&S41&$R$9&J41&$S$10&K41&$R$8&I41 -> Cước vận chuyển Container hàng 40' tuyến đường PAN HA - HẢI AN,. BKS: 15C17442 | S41: =IF(E41=1," hàng 20' ",IF(F41=1," hàng 40' "," vỏ ")) -> hàng 40' | V41: 2
...

Sheet Sheet1
A3: HATECO | B3: PAN HẢI AN | C3: CHUYỂN BÃI | D3: MSK | E3: HASU4838528 | F3: 40HC | G3: E | H3: =F3&G3 -> 40HCE | I3: =A3 -> HATECO | J3: 15H07644 | K3: PHÚC LỘC
A4: HATECO | B4: PAN HẢI AN | C4: CHUYỂN BÃI | D4: MSK | E4: GCXU6254324 | F4: 40HC | G4: E | H4: =F4&G4 -> 40HCE | I4: =A4 -> HATECO | J4: 15H15378 | K4: PHÚC LỘC
A5: HATECO | B5: PAN HẢI AN | C5: CHUYỂN BÃI | D5: MSK | E5: MRKU2870533 | F5: 40HC | G5: E | H5: =F5&G5 -> 40HCE | I5: =A5 -> HATECO | J5: 15H07788 | K5: PHÚC LỘC
A6: HATECO | B6: PAN HẢI AN | C6: CHUYỂN BÃI | D6: MSK | E6: MRSU5143968 | F6: 40HC | G6: E | H6: =F6&G6 -> 40HCE | I6: =A6 -> HATECO | J6: 15H07644 | K6: PHÚC LỘC
A7: HATECO | B7: PAN HẢI AN | C7: CHUYỂN BÃI | D7: HLL | E7: GCXU2335705 | F7: 20GP | G7: E | H7: =F7&G7 -> 20GPE | I7: =A7 -> HATECO | J7: 15H18552 | K7: PHÚC LỘC | L7: WO 801164881
A8: HATECO | B8: PAN HẢI AN | C8: CHUYỂN BÃI | D8: HLL | E8: UACU3879903 | F8: 20GP | G8: E | H8: =F8&G8 -> 20GPE | I8: =A8 -> HATECO | J8: 15H18552 | K8: PHÚC LỘC | L8: WO 801164881
A9: HATECO | B9: PAN HẢI AN | C9: CHUYỂN BÃI | D9: HLL | E9: BMOU1256909 | F9: 20GP | G9: E | H9: =F9&G9 -> 20GPE | I9: =A9 -> HATECO | J9: 15H18552 | K9: PHÚC LỘC | L9: WO 801164881
A10: HATECO | B10: PAN HẢI AN | C10: CHUYỂN BÃI | D10: HLL | E10: BSIU2530157 | F10: 20GP | G10: E | H10: =F10&G10 -> 20GPE | I10: =A10 -> HATECO | J10: 15H18552 | K10: PHÚC LỘC | L10: WO 801164881
A11: HATECO | B11: PAN HẢI AN | C11: CHUYỂN BÃI | D11: HLL | E11: UACU5741889 | F11: 40HC | G11: E | H11: =F11&G11 -> 40HCE | I11: =A11 -> HATECO | J11: 15C17301 | K11: PHÚC LỘC | L11: WO 801164881
A12: HATECO | B12: PAN HẢI AN | C12: CHUYỂN BÃI | D12: HLL | E12: HLBU2188273 | F12: 40HC | G12: E | H12: =F12&G12 -> 40HCE | I12: =A12 -> HATECO | J12: 15H17712 | K12: PHÚC LỘC | L12: WO 801164881
A13: HATECO | B13: PAN HẢI AN | C13: CHUYỂN BÃI | D13: HLL | E13: HAMU1395846 | F13: 40HC | G13: E | H13: =F13&G13 -> 40HCE | I13: =A13 -> HATECO | J13: 15C17301 | K13: PHÚC LỘC | L13: WO 801164881
A14: HATECO | B14: PAN HẢI AN | C14: CHUYỂN BÃI | D14: HLL | E14: HAMU2715158 | F14: 40HC | G14: E | H14: =F14&G14 -> 40HCE | I14: =A14 -> HATECO | J14: 15H17712 | K14: PHÚC LỘC | L14: WO 801164881
A15: HATECO | B15: PAN HẢI AN | C15: CHUYỂN BÃI | D15: HLL | E15: HLBU1567930 | F15: 40HC | G15: E | H15: =F15&G15 -> 40HCE | I15: =A15 -> HATECO | J15: 15H17712 | K15: PHÚC LỘC | L15: WO 801164881
A16: HATECO | B16: PAN HẢI AN | C16: CHUYỂN BÃI | D16: HLL | E16: HAMU3816923 | F16: 40HC | G16: E | H16: =F16&G16 -> 40HCE | I16: =A16 -> HATECO | J16: 15H17712 | K16: PHÚC LỘC | L16: WO 801164881
A17: HATECO | B17: PAN HẢI AN | C17: CHUYỂN BÃI | D17: HLL | E17: HAMU1331878 | F17: 40HC | G17: E | H17: =F17&G17 -> 40HCE | I17: =A17 -> HATECO | J17: 15C17442 | K17: PHÚC LỘC | L17: WO 801164881
A18: HATECO | B18: PAN HẢI AN | C18: CHUYỂN BÃI | D18: HLL | E18: HLBU3145065 | F18: 40HC | G18: E | H18: =F18&G18 -> 40HCE | I18: =A18 -> HATECO | J18: 15H15378 | K18: PHÚC LỘC | L18: WO 801164881
A19: HATECO | B19: PAN HẢI AN | C19: CHUYỂN BÃI | D19: MSK | E19: MSKU4652300 | F19: 45HC | G19: E | H19: =F19&G19 -> 45HCE | I19: =A19 -> HATECO | J19: 15H12925 | K19: PHÚC LỘC
A20: HATECO | B20: PAN HẢI AN | C20: CHUYỂN BÃI | D20: MSK | E20: MSKU4643232 | F20: 45HC | G20: E | H20: =F20&G20 -> 45HCE | I20: =A20 -> HATECO | J20: 15H07788 | K20: PHÚC LỘC
A21: HATECO | B21: PAN HẢI AN | C21: CHUYỂN BÃI | D21: MSK | E21: MSKU4783044 | F21: 45HC | G21: E | H21: =F21&G21 -> 45HCE | I21: =A21 -> HATECO | J21: 15H09877 | K21: PHÚC LỘC
A22: HATECO | B22: PAN HẢI AN | C22: CHUYỂN BÃI | D22: MSK | E22: MAEU9258570 | F22: 45HC | G22: E | H22: =F22&G22 -> 45HCE | I22: =A22 -> HATECO | J22: 15H12925 | K22: PHÚC LỘC
A23: HATECO | B23: PAN HẢI AN | C23: CHUYỂN BÃI | D23: MSK | E23: MAEU9211845 | F23: 45HC | G23: E | H23: =F23&G23 -> 45HCE | I23: =A23 -> HATECO | J23: 15H07788 | K23: PHÚC LỘC
A24: NAM HẢI ĐÌNH VŨ | B24: PAN HẢI AN | C24: CHUYỂN BÃI | D24: HAC1 | E24: SELU4506699 | F24: 40HC | G24: E | H24: =F24&G24 -> 40HCE | I24: =A24 -> NAM HẢI ĐÌNH VŨ | J24: 15H07644 | K24: PHÚC LỘC
A25: NAM HẢI ĐÌNH VŨ | B25: PAN HẢI AN | C25: CHUYỂN BÃI | D25: HAC1 | E25: BEAU5404321 | F25: 40HC | G25: E | H25: =F25&G25 -> 40HCE | I25: =A25 -> NAM HẢI ĐÌNH VŨ | J25: 15H18552 | K25: PHÚC LỘC
A26: NAM HẢI ĐÌNH VŨ | B26: PAN HẢI AN | C26: CHUYỂN BÃI | D26: HAC1 | E26: BEAU5406411 | F26: 40HC | G26: E | H26: =F26&G26 -> 40HCE | I26: =A26 -> NAM HẢI ĐÌNH VŨ | J26: 15C15033 | K26: PHÚC LỘC
A27: NAM HẢI ĐÌNH VŨ | B27: PAN HẢI AN | C27: CHUYỂN BÃI | D27: HAC1 | E27: WBPU7051107 | F27: 40HC | G27: E | H27: =F27&G27 -> 40HCE | I27: =A27 -> NAM HẢI ĐÌNH VŨ | J27: 15H07644 | K27: PHÚC LỘC
A28: NAM HẢI ĐÌNH VŨ | B28: PAN HẢI AN | C28: CHUYỂN BÃI | D28: HAC1 | E28: FBLU0021428 | F28: 40HC | G28: E | H28: =F28&G28 -> 40HCE | I28: =A28 -> NAM HẢI ĐÌNH VŨ | J28: 15C17301 | K28: PHÚC LỘC
A29: NAM HẢI ĐÌNH VŨ | B29: PAN HẢI AN | C29: CHUYỂN BÃI | D29: HAC1 | E29: SELU4563596 | F29: 40HC | G29: E | H29: =F29&G29 -> 40HCE | I29: =A29 -> NAM HẢI ĐÌNH VŨ | J29: 15H07524 | K29: PHÚC LỘC
A30: NAM HẢI ĐÌNH VŨ | B30: PAN HẢI AN | C30: CHUYỂN BÃI | D30: HAC1 | E30: CAIU4287185 | F30: 40HC | G30: E | H30: =F30&G30 -> 40HCE | I30: =A30 -> NAM HẢI ĐÌNH VŨ | J30: 15H08574 | K30: PHÚC LỘC
... A99: HATECO | B99: PAN HẢI AN | C99: CHUYỂN BÃI | D99: MSK | E99: TCNU2732639 | F99: 40HC | G99: E | H99: =F99&G99 -> 40HCE | I99: =A99 -> HATECO | J99: 15H20645 | K99: PHÚC LỘC
A100: HATECO | B100: PAN HẢI AN | C100: CHUYỂN BÃI | D100: HLL | E100: HLBU2447672 | F100: 40HC | G100: E | H100: =F100&G100 -> 40HCE | I100: =A100 -> HATECO | J100: 15C17301 | K100: PHÚC LỘC | L100: WO 801172589
A101: HATECO | B101: PAN HẢI AN | C101: CHUYỂN BÃI | D101: HLL | E101: HLXU8486138 | F101: 40HC | G101: E | H101: =F101&G101 -> 40HCE | I101: =A101 -> HATECO | J101: 15H09877 | K101: PHÚC LỘC | L101: WO 801172589
A102: HATECO | B102: PAN HẢI AN | C102: CHUYỂN BÃI | D102: HLL | E102: BEAU5170162 | F102: 40HC | G102: E | H102: =F102&G102 -> 40HCE | I102: =A102 -> HATECO | J102: 15C17442 | K102: PHÚC LỘC | L102: WO 801172589
A103: HATECO | B103: PAN HẢI AN | C103: CHUYỂN BÃI | D103: HLL | E103: HAMU2058027 | F103: 40HC | G103: E | H103: =F103&G103 -> 40HCE | I103: =A103 -> HATECO | J103: 15C21728 | K103: PHÚC LỘC | L103: WO 801172589
A104: HATECO | B104: PAN HẢI AN | C104: CHUYỂN BÃI | D104: HLL | E104: HAMU3363133 | F104: 40HC | G104: E | H104: =F104&G104 -> 40HCE | I104: =A104 -> HATECO | J104: 15H18552 | K104: PHÚC LỘC | L104: WO 801172589
A105: HATECO | B105: PAN HẢI AN | C105: CHUYỂN BÃI | D105: HLL | E105: HLBU1930496 | F105: 40HC | G105: E | H105: =F105&G105 -> 40HCE | I105: =A105 -> HATECO | J105: 15H08574 | K105: PHÚC LỘC | L105: WO 801172589
A106: HATECO | B106: PAN HẢI AN | C106: CHUYỂN BÃI | D106: HLL | E106: HAMU3142180 | F106: 40HC | G106: E | H106: =F106&G106 -> 40HCE | I106: =A106 -> HATECO | J106: 15C30649 | K106: PHÚC LỘC | L106: WO 801172589
A107: HATECO | B107: PAN HẢI AN | C107: CHUYỂN BÃI | D107: HLL | E107: TCNU1860506 | F107: 40HC | G107: E | H107: =F107&G107 -> 40HCE | I107: =A107 -> HATECO | J107: 15H20645 | K107: PHÚC LỘC | L107: WO 801172589
A108: HATECO | B108: PAN HẢI AN | C108: CHUYỂN BÃI | D108: HLL | E108: HAMU1705453 | F108: 40HC | G108: E | H108: =F108&G108 -> 40HCE | I108: =A108 -> HATECO | J108: 15C17442 | K108: PHÚC LỘC | L108: WO 801172589
A109: HATECO | B109: PAN HẢI AN | C109: CHUYỂN BÃI | D109: HLL | E109: UACU5631433 | F109: 40HC | G109: E | H109: =F109&G109 -> 40HCE | I109: =A109 -> HATECO | J109: 15H09877 | K109: PHÚC LỘC | L109: WO 801172589
A110: HATECO | B110: PAN HẢI AN | C110: CHUYỂN BÃI | D110: HLL | E110: FSCU8238062 | F110: 40HC | G110: E | H110: =F110&G110 -> 40HCE | I110: =A110 -> HATECO | J110: 15C17301 | K110: PHÚC LỘC | L110: WO 801172589
...

Sheet Sheet4
A3: Row Labels | B3: Sum of SỐ CHUYẾN | C3: Sum of CƯỚC CHUYẾN
A4: Cước vận chuyển Container hàng 20' tuyến đường PAN HA - HẢI AN. BKS: 15C09877 | B4: 42 | C4: 27504582 | E4: 42 | F4: 27504582 | G4: =F4/E4 -> 654871
A5: Cước vận chuyển Container hàng 20' tuyến đường PAN HA - HẢI AN. BKS: 15C15033 | B5: 40 | C5: 26194840 | E5: 40 | F5: 26194840 | G5: =F5/E5 -> 654871
A6: Cước vận chuyển Container hàng 20' tuyến đường PAN HA - HẢI AN. BKS: 15C17301 | B6: 27 | C6: 17681517 | E6: 27 | F6: 17681517 | G6: =F6/E6 -> 654871
A7: Cước vận chuyển Container hàng 20' tuyến đường PAN HA - HẢI AN. BKS: 15C17442 | B7: 32 | C7: 20955872 | E7: 32 | F7: 20955872 | G7: =F7/E7 -> 654871
A8: Cước vận chuyển Container hàng 20' tuyến đường PAN HA - HẢI AN. BKS: 15C30649 | B8: 29 | C8: 18991259 | E8: 29 | F8: 18991259 | G8: =F8/E8 -> 654871
A9: Cước vận chuyển Container hàng 20' tuyến đường PAN HA - HẢI AN. BKS: 15H06892 | B9: 8 | C9: 5238968 | E9: 8 | F9: 5238968 | G9: =F9/E9 -> 654871
A10: Cước vận chuyển Container hàng 20' tuyến đường PAN HA - HẢI AN. BKS: 15H07135 | B10: 8 | C10: 5238968 | E10: 8 | F10: 5238968 | G10: =F10/E10 -> 654871
A11: Cước vận chuyển Container hàng 20' tuyến đường PAN HA - HẢI AN. BKS: 15H07524 | B11: 36 | C11: 23575356 | E11: 36 | F11: 23575356 | G11: =F11/E11 -> 654871
A12: Cước vận chuyển Container hàng 20' tuyến đường PAN HA - HẢI AN. BKS: 15H07644 | B12: 20 | C12: 13097420 | E12: 20 | F12: 13097420 | G12: =F12/E12 -> 654871
A13: Cước vận chuyển Container hàng 20' tuyến đường PAN HA - HẢI AN. BKS: 15H07788 | B13: 24 | C13: 15716904 | E13: 24 | F13: 15716904 | G13: =F13/E13 -> 654871
A14: Cước vận chuyển Container hàng 20' tuyến đường PAN HA - HẢI AN. BKS: 15H08574 | B14: 29 | C14: 18991259 | E14: 29 | F14: 18991259 | G14: =F14/E14 -> 654871
A15: Cước vận chuyển Container hàng 20' tuyến đường PAN HA - HẢI AN. BKS: 15H12925 | B15: 3 | C15: 1964613 | E15: 3 | F15: 1964613 | G15: =F15/E15 -> 654871
... A166: Cước vận chuyển Container vỏ tuyến đường PAN HA - VIP. BKS: 15H20645 | B166: 7 | C166: 3851057 | E166: 7 | F166: 3851057 | G166: =F166/E166 -> 550151
A167: (blank)
A168: Grand Total | B168: 1169 | C168: 764422896

Sheet HĐơn
A1: Nội dung HĐ | B1: SỐ CHUYẾN | C1: CƯỚC CHUYẾN
A2: Cước vận chuyển Container hàng 20' tuyến đường PAN HA - NDV. BKS: 15C17442 | B2: 1 | C2: 454158
A3: Cước vận chuyển Container hàng 40' tuyến đường PAN HA - NDV. BKS: 15C17442 | B3: 1 | C3: 489065
A4: Cước vận chuyển Container vỏ tuyến đường HATECO - PAN HA. BKS: 15C17442 | B4: 1 | C4: 1002400
A5: Cước vận chuyển Container vỏ tuyến đường HATECO - PAN HA. BKS: 15H07644 | B5: 1 | C5: 1002400
A6: Cước vận chuyển Container vỏ tuyến đường HATECO - PAN HA. BKS: 15H07644 | B6: 1 | C6: 1002400
A7: Cước vận chuyển Container vỏ tuyến đường HATECO - PAN HA. BKS: 15H07788 | B7: 1 | C7: 1002400
A8: Cước vận chuyển Container hàng 20' tuyến đường PAN HA - HẢI AN. BKS: 15H12925 | B8: 1 | C8: 654871
A9: Cước vận chuyển Container hàng 40' tuyến đường PAN HA - HẢI AN. BKS: 15H12925 | B9: 1 | C9: 681050
A10: Cước vận chuyển Container hàng 40' tuyến đường PAN HA - HẢI AN. BKS: 15H12925 | B10: 1 | C10: 681050
A11: Cước vận chuyển Container hàng 40' tuyến đường PAN HA - HẢI AN. BKS: 15H12925 | B11: 1 | C11: 681050
A12: Cước vận chuyển Container hàng 20' tuyến đường PAN HA - HẢI AN. BKS: 15H07524 | B12: 1 | C12: 654871
A13: Cước vận chuyển Container hàng 20' tuyến đường PAN HA - HẢI AN. BKS: 15H07524 | B13: 1 | C13: 654871
... A1208: Cước vận chuyển Container vỏ tuyến đường PAN HA - HẢI AN. BKS: 15C17442 | B1208: 1 | C1208: 628690

Sheet Trucking (HD)
A2: ĐỀ XUẤT ĐIỀU CHỈNH ĐƠN GIÁ VẬN TẢI PHÚC LỘC 2026 | Q2: ĐIỀU CHỈNH TĂNG TỪ 7-2025
A4: 2. VẬN CHUYỂN SHIPSIDE HÀNG/VỎ XUẤT TÀU: | D4: =D7*1.12 -> 201824
A5: STT | B5: TUYẾN VẬN CHUYỂN | D5: Mức 1 hiện tại T8 - 2021 (dưới 22.000/lít) | G5: Vendor đề xuất (tối thiểu 15%) | J5: Pan đề xuất (tăng 15% tuyến chính, 10% tuyến phụ, 7% HICT) | M5: Ghi chú | N5: ĐƠN GIÁ GỬI 80.000đ | Q5: Tăng tiền gửi từ 80,000 -> 140,000 | T5: ĐIỀU CHỈNH TĂNG 12% TỪ 01/01/2026. GIÁ GỐC CHƯA GỬI | W5: GIÁ CHUẨN TỪ 1/1/2026 | Z5: Đơn giá chưa gửi đang áp dụng 2026 | AC5: ĐƠN GIÁ TRUCKING THÁNG 03/2026 NHÂN TỶ LỆ TĂNG GIÁ DẦU | AG5: ĐƠN GIÁ T03.26 ĐÃ CỘNG GIÁ GỬI - KÝ PHỤ LỤC | AJ5: ĐƠN GIÁ T04.26 ĐÃ CỘNG GIÁ GỬI - KÝ PHỤ LỤC
D6: Vỏ | E6: Hàng 20' | F6: Hàng 40&45 | G6: Vỏ | H6: Hàng 20' | I6: Hàng 40&45 | J6: Vỏ | K6: Hàng 20' | L6: Hàng 40&45 | N6: Vỏ | O6: Hàng 20' | P6: Hàng 40&45 | Q6: Vỏ | R6: Hàng 20' | S6: Hàng 40&45 | T6: Vỏ | U6: Hàng 20' | V6: Hàng 40&45 | W6: Vỏ | X6: Hàng 20' | Y6: Hàng 40&45 | Z6: Vỏ | AA6: Hàng 20' | AB6: Hàng 40&45 | AC6: Vỏ | AD6: Hàng 20' | AE6: Hàng 40&45 | AF6: Tăng | AG6: Vỏ | AH6: Hàng 20' | AI6: Hàng 40&45 | AJ6: Vỏ | AK6: Hàng 20' | AL6: Hàng 40&45
A7: 1 | B7: PAN HA – NAM ĐÌNH VŨ | D7: 180200 | E7: 190800 | F7: 212000 | G7: =D7*1.15 -> 207230 | H7: =E7*1.15 -> 219420 | I7: =F7*1.15 -> 243800 | J7: =D7*1.15 -> 207230 | K7: =E7*1.15 -> 219420 | L7: =F7*1.15 -> 243800 | M7: Tăng 15% | N7: =+J7+80000 -> 287230 | O7: =+K7+80000 -> 299420 | P7: =+L7+80000 -> 323800 | Q7: =N7+60000 -> 347230 | R7: =O7+60000 -> 359420 | S7: =P7+60000 -> 383800 | T7: =+J7*112% -> 232097.6 | U7: =+K7*112% -> 245750.4 | V7: =+L7*112% -> 273056 | W7: =ROUND(T7+140000,0) -> 372098 | X7: =ROUND(U7+140000,0) -> 385750 | Y7: =ROUND(V7+140000,0) -> 413056 | Z7: =W7-140000 -> 232098 | AA7: =X7-140000 -> 245750 | AB7: =Y7-140000 -> 273056 | AC7: =ROUND((Z7*35%*'[1]Giá dầu'!$E$20)+Z7,0) -> 263979 | AD7: =ROUND((AA7*35%*'[1]Giá dầu'!$E$20)+AA7,0) -> 279506 | AE7: =ROUND((AB7*35%*'[1]Giá dầu'!$E$20)+AB7,0) -> 310563 | AF7: =(AC7-Z7)/Z7 -> 0.13736008 | AG7: =AC7+140000 -> 403979 | AH7: =AD7+140000 -> 419506 | AI7: =AE7+140000 -> 450563 | AJ7: 436705 | AK7: 454158 | AL7: 489065
A8: 2 | B8: PAN HA – NAM HẢI ĐÌNH VŨ/VIP GREENPORT/ G – FORTUNE | D8: 249100 | E8: 265000 | F8: 280900 | G8: =D8*1.15 -> 286465 | H8: =E8*1.15 -> 304750 | I8: =F8*1.15 -> 323035 | J8: =D8*1.15 -> 286465 | K8: =E8*1.15 -> 304750 | L8: =F8*1.15 -> 323035 | M8: Tăng 15% | N8: =+J8+80000 -> 366465 | O8: =+K8+80000 -> 384750 | P8: =+L8+80000 -> 403035 | Q8: =N8+60000 -> 426465 | R8: =O8+60000 -> 444750 | S8: =P8+60000 -> 463035 | T8: =+J8*112% -> 320840.8 | U8: =+K8*112% -> 341320 | V8: =+L8*112% -> 361799.2 | W8: =ROUND(T8+140000,0) -> 460841 | X8: =ROUND(U8+140000,0) -> 481320 | Y8: =ROUND(V8+140000,0) -> 501799 | Z8: =W8-140000 -> 320841 | AA8: =X8-140000 -> 341320 | AB8: =Y8-140000 -> 361799 | AC8: =ROUND((Z8*35%*'[1]Giá dầu'!$E$20)+Z8,0) -> 364912 | AD8: =ROUND((AA8*35%*'[1]Giá dầu'!$E$20)+AA8,0) -> 388204 | AE8: =ROUND((AB8*35%*'[1]Giá dầu'!$E$20)+AB8,0) -> 411496 | AF8: =(AC8-Z8)/Z8 -> 0.13736087 | AG8: =AC8+140000 -> 504912 | AH8: =AD8+140000 -> 528204 | AI8: =AE8+140000 -> 551496 | AJ8: 550151 | AK8: 576331 | AL8: 602510
A9: 3 | B9: PAN HA – ĐÌNH VŨ/TÂN VŨ, ICD TÂN CẢNG | D9: 265000 | E9: 275600 | F9: 296800 | G9: =D9*1.15 -> 304750 | H9: =E9*1.15 -> 316940 | I9: =F9*1.15 -> 341320 | J9: =D9*1.15 -> 304750 | K9: =E9*1.15 -> 316940 | L9: =F9*1.15 -> 341320 | M9: Tăng 15% | N9: =+J9+80000 -> 384750 | O9: =+K9+80000 -> 396940 | P9: =+L9+80000 -> 421320 | Q9: =N9+60000 -> 444750 | R9: =O9+60000 -> 456940 | S9: =P9+60000 -> 481320 | T9: =+J9*112% -> 341320 | U9: =+K9*112% -> 354972.8 | V9: =+L9*112% -> 382278.4 | W9: =ROUND(T9+140000,0) -> 481320 | X9: =ROUND(U9+140000,0) -> 494973 | Y9: =ROUND(V9+140000,0) -> 522278 | Z9: =W9-140000 -> 341320 | AA9: =X9-140000 -> 354973 | AB9: =Y9-140000 -> 382278 | AC9: =ROUND((Z9*35%*'[1]Giá dầu'!$E$20)+Z9,0) -> 388204 | AD9: =ROUND((AA9*35%*'[1]Giá dầu'!$E$20)+AA9,0) -> 403732 | AE9: =ROUND((AB9*35%*'[1]Giá dầu'!$E$20)+AB9,0) -> 434788 | AF9: =(AC9-Z9)/Z9 -> 0.13736083 | AG9: =AC9+140000 -> 528204 | AH9: =AD9+140000 -> 543732 | AI9: =AE9+140000 -> 574788 | AJ9: 576331 | AK9: 593784 | AL9: 628690
A10: 4 | B10: PAN HA – PTSC ĐÌNH VŨ | D10: 275600 | E10: 286200 | F10: 307400 | G10: =D10*1.15 -> 316940 | H10: =E10*1.15 -> 329130 | I10: =F10*1.15 -> 353510 | J10: =D10*1.15 -> 316940 | K10: =E10*1.15 -> 329130 | L10: =F10*1.15 -> 353510 | M10: Tăng 15% | N10: =+J10+80000 -> 396940 | O10: =+K10+80000 -> 409130 | P10: =+L10+80000 -> 433510 | Q10: =N10+60000 -> 456940 | R10: =O10+60000 -> 469130 | S10: =P10+60000 -> 493510 | T10: =+J10*112% -> 354972.8 | U10: =+K10*112% -> 368625.6 | V10: =+L10*112% -> 395931.2 | W10: =ROUND(T10+140000,0) -> 494973 | X10: =ROUND(U10+140000,0) -> 508626 | Y10: =ROUND(V10+140000,0) -> 535931 | Z10: =W10-140000 -> 354973 | AA10: =X10-140000 -> 368626 | AB10: =Y10-140000 -> 395931 | AC10: =ROUND((Z10*35%*'[1]Giá dầu'!$E$20)+Z10,0) -> 403732 | AD10: =ROUND((AA10*35%*'[1]Giá dầu'!$E$20)+AA10,0) -> 419261 | AE10: =ROUND((AB10*35%*'[1]Giá dầu'!$E$20)+AB10,0) -> 450316 | AF10: =(AC10-Z10)/Z10 -> 0.13735974 | AG10: =AC10+140000 -> 543732 | AH10: =AD10+140000 -> 559261 | AI10: =AE10+140000 -> 590316 | AJ10: 593784 | AK10: 611238 | AL10: 646143
A11: 5 | B11: PAN HA – TC 189 | D11: 291500 | E11: 296800 | F11: 318000 | G11: =D11*1.15 -> 335225 | H11: =E11*1.15 -> 341320 | I11: =F11*1.15 -> 365700 | J11: =D11*1.15 -> 335225 | K11: =E11*1.15 -> 341320 | L11: =F11*1.15 -> 365700 | M11: Tăng 15% | N11: =+J11+80000 -> 415225 | O11: =+K11+80000 -> 421320 | P11: =+L11+80000 -> 445700 | Q11: =N11+60000 -> 475225 | R11: =O11+60000 -> 481320 | S11: =P11+60000 -> 505700 | T11: =+J11*112% -> 375452 | U11: =+K11*112% -> 382278.4 | V11: =+L11*112% -> 409584 | W11: =ROUND(T11+140000,0) -> 515452 | X11: =ROUND(U11+140000,0) -> 522278 | Y11: =ROUND(V11+140000,0) -> 549584 | Z11: =W11-140000 -> 375452 | AA11: =X11-140000 -> 382278 | AB11: =Y11-140000 -> 409584 | AC11: =ROUND((Z11*35%*'[1]Giá dầu'!$E$20)+Z11,0) -> 427024 | AD11: =ROUND((AA11*35%*'[1]Giá dầu'!$E$20)+AA11,0) -> 434788 | AE11: =ROUND((AB11*35%*'[1]Giá dầu'!$E$20)+AB11,0) -> 465845 | AF11: =(AC11-Z11)/Z11 -> 0.13735977 | AG11: =AC11+140000 -> 567024 | AH11: =AD11+140000 -> 574788 | AI11: =AE11+140000 -> 605845 | AJ11: 619964 | AK11: 628690 | AL11: 663597
A12: 6 | B12: PAN HA – HAI AN | D12: 296800 | E12: 312700 | F12: 328600 | G12: =D12*1.15 -> 341320 | H12: =E12*1.15 -> 359605 | I12: =F12*1.15 -> 377890 | J12: =D12*1.15 -> 341320 | K12: =E12*1.15 -> 359605 | L12: =F12*1.15 -> 377890 | M12: Tăng 15% | N12: =+J12+80000 -> 421320 | O12: =+K12+80000 -> 439605 | P12: =+L12+80000 -> 457890 | Q12: =N12+60000 -> 481320 | R12: =O12+60000 -> 499605 | S12: =P12+60000 -> 517890 | T12: =+J12*112% -> 382278.4 | U12: =+K12*112% -> 402757.6 | V12: =+L12*112% -> 423236.8 | W12: =ROUND(T12+140000,0) -> 522278 | X12: =ROUND(U12+140000,0) -> 542758 | Y12: =ROUND(V12+140000,0) -> 563237 | Z12: =W12-140000 -> 382278 | AA12: =X12-140000 -> 402758 | AB12: =Y12-140000 -> 423237 | AC12: =ROUND((Z12*35%*'[1]Giá dầu'!$E$20)+Z12,0) -> 434788 | AD12: =ROUND((AA12*35%*'[1]Giá dầu'!$E$20)+AA12,0) -> 458081 | AE12: =ROUND((AB12*35%*'[1]Giá dầu'!$E$20)+AB12,0) -> 481373 | AF12: =(AC12-Z12)/Z12 -> 0.13736077 | AG12: =AC12+140000 -> 574788 | AH12: =AD12+140000 -> 598081 | AI12: =AE12+140000 -> 621373 | AJ12: 628690 | AK12: 654871 | AL12: 681050
